Workbook
Name FID_1: [1]AGR_Fuels!$A$2

Sheet Region-Time Slices
B3: ~BookRegions_Map | H3: ~TimeSlices
B4: BookName | C4: Region | H4: Season | I4: Weekly | J4: DayNite
B5: EE | C5: EE | H5: S01 | J5: H01
H6: S02 | J6: H02
H7: S03 | J7: H03
H8: S04 | J8: H04
J9: H05
J10: H06

Sheet TimePeriods
B3: ~StartYear | D3: ~DefaultYear
B4: 2025 | D4: =B4 -> 2025
B7: ~ActivePDef
B8: P1
B11: ~TimePeriods | H11: ~Milestoneyears
B12: P1 | D12: S | E12: M | F12: E | H12: type | I12: ="msy"&COUNT(E14:E47)&"_"&MAX(E14:E47) -> msy6_2050 | K12: B | L12: E
B13: 1 | D13: =B4 -> 2025 | E13: =AVERAGE(D13,F13) -> 2025 | F13: =B4 -> 2025 | H13: endyear | I13: 2052
B14: 2 | D14: =F13+1 -> 2026 | E14: 2026 | F14: =F13+B14 -> 2027 | H14: milestoneyear | I14: =$B$4 -> 2025 | K14: =B4 -> 2025 | L14: =FLOOR((I14+I15)/2,1) -> 2025
B15: 5 | D15: =F14+1 -> 2028 | E15: =AVERAGE(D15,F15) -> 2030 | F15: =F14+B15 -> 2032 | H15: milestoneyear | I15: 2026 | K15: =L14+1 -> 2026 | L15: =FLOOR((I15+I16)/2,1) -> 2028
B16: 5 | D16: =F15+1 -> 2033 | E16: =AVERAGE(D16,F16) -> 2035 | F16: =F15+B16 -> 2037 | H16: milestoneyear | I16: 2030 | K16: =L15+1 -> 2029 | L16: =FLOOR((I16+I17)/2,1) -> 2032
B17: 5 | D17: =F16+1 -> 2038 | E17: =AVERAGE(D17,F17) -> 2040 | F17: =F16+B17 -> 2042 | H17: milestoneyear | I17: =I16+5 -> 2035 | K17: =L16+1 -> 2033 | L17: =FLOOR((I17+I18)/2,1) -> 2037
B18: 5 | D18: =F17+1 -> 2043 | E18: =AVERAGE(D18,F18) -> 2045 | F18: =F17+B18 -> 2047 | H18: milestoneyear | I18: =I17+5 -> 2040 | K18: =L17+1 -> 2038 | L18: =FLOOR((I18+I19)/2,1) -> 2042
B19: 5 | D19: =F18+1 -> 2048 | E19: =AVERAGE(D19,F19) -> 2050 | F19: =F18+B19 -> 2052 | H19: milestoneyear | I19: =I18+5 -> 2045 | K19: =L18+1 -> 2043 | L19: =FLOOR((I19+I20)/2,1) -> 2047
H20: milestoneyear | I20: =I19+5 -> 2050 | K20: =L19+1 -> 2048
H21: milestoneyear
H22: milestoneyear
H23: milestoneyear
H24: milestoneyear
H25: milestoneyear
H26: milestoneyear
H27: milestoneyear
H28: milestoneyear
H29: milestoneyear

Sheet Interpol_Extrapol_Defaults
B3: ~TFM_MIG
B4: TimeSlice | C4: LimType | D4: Attribute | E4: Year2 | F4: AllRegions | G4: Pset_PN
C5: UP | D5: ACT_BND | E5: 0 | F5: 5
B28: *Set a default price or apply a factor for those IMPorts with "Z" in the name.
B30: Dummy Imp Prices
B31: ~TFM_UPD
B32: TimeSlice | C32: LimType | D32: Attribute | E32: Year | F32: Other_Indexes | G32: AllRegions | H32: REG1 | I32: REG2 | J32: Pset_Set | K32: Pset_PN | L32: Pset_PD | M32: Pset_CI | N32: Pset_CO | O32: Cset_Set | P32: Cset_CN | Q32: Cset_CD
D33: ACTCOST | G33: 2222 | J33: IRE | K33: IMP*Z
D34: ACTCOST | G34: 8888 | J34: IRE | K34: IMPDEMZ
B37: ~TFM_INS
B38: Attribute | C38: AllRegions | D38: Pset_Set | E38: Pset_PN
B39: PRC_TSL | C39: DAYNITE | D39: IRE | E39: IMP*Z

Sheet Constants
B3: * Define constants for the model
B5: ~TFM_INS
B6: TimeSlice | C6: LimType | D6: Attribute | E6: AllRegions
D7: G_DYEAR | E7: 2025
D8: Discount | E8: 0.05
B9: ='Region-Time Slices'!$H$5&'Region-Time Slices'!J5 -> S01H01 | D9: YRFR | E9: =K48 -> 0.041666667
B10: ='Region-Time Slices'!$H$5&'Region-Time Slices'!J6 -> S01H02 | D10: YRFR | E10: =K49 -> 0.041666667
B11: ='Region-Time Slices'!$H$5&'Region-Time Slices'!J7 -> S01H03 | D11: YRFR | E11: =K50 -> 0.041666667
B12: ='Region-Time Slices'!$H$5&'Region-Time Slices'!J8 -> S01H04 | D12: YRFR | E12: =K51 -> 0.041666667
B13: ='Region-Time Slices'!$H$5&'Region-Time Slices'!J9 -> S01H05 | D13: YRFR | E13: =K52 -> 0.041666667
B14: ='Region-Time Slices'!$H$5&'Region-Time Slices'!J10 -> S01H06 | D14: YRFR | E14: =K53 -> 0.041666667
B15: ='Region-Time Slices'!$H$6&'Region-Time Slices'!J5 -> S02H01 | D15: YRFR | E15: =L48 -> 0.041666667
B16: ='Region-Time Slices'!$H$6&'Region-Time Slices'!J6 -> S02H02 | D16: YRFR | E16: =L49 -> 0.041666667
B17: ='Region-Time Slices'!$H$6&'Region-Time Slices'!J7 -> S02H03 | D17: YRFR | E17: =L50 -> 0.041666667
B18: ='Region-Time Slices'!$H$6&'Region-Time Slices'!J8 -> S02H04 | D18: YRFR | E18: =L51 -> 0.041666667
B19: ='Region-Time Slices'!$H$6&'Region-Time Slices'!J9 -> S02H05 | D19: YRFR | E19: =L52 -> 0.041666667
B20: ='Region-Time Slices'!$H$6&'Region-Time Slices'!J10 -> S02H06 | D20: YRFR | E20: =L53 -> 0.041666667
B21: ='Region-Time Slices'!$H$7&'Region-Time Slices'!J5 -> S03H01 | D21: YRFR | E21: =M48 -> 0.041666667
B22: ='Region-Time Slices'!$H$7&'Region-Time Slices'!J6 -> S03H02 | D22: YRFR | E22: =M49 -> 0.041666667
B23: ='Region-Time Slices'!$H$7&'Region-Time Slices'!J7 -> S03H03 | D23: YRFR | E23: =M50 -> 0.041666667
B24: ='Region-Time Slices'!$H$7&'Region-Time Slices'!J8 -> S03H04 | D24: YRFR | E24: =M51 -> 0.041666667
B25: ='Region-Time Slices'!$H$7&'Region-Time Slices'!J9 -> S03H05 | D25: YRFR | E25: =M52 -> 0.041666667
B26: ='Region-Time Slices'!$H$7&'Region-Time Slices'!J10 -> S03H06 | D26: YRFR | E26: =M53 -> 0.041666667
B27: ='Region-Time Slices'!$H$8&'Region-Time Slices'!J5 -> S04H01 | D27: YRFR | E27: =N48 -> 0.041666667
B28: ='Region-Time Slices'!$H$8&'Region-Time Slices'!J6 -> S04H02 | D28: YRFR | E28: =N49 -> 0.041666667
B29: ='Region-Time Slices'!$H$8&'Region-Time Slices'!J7 -> S04H03 | D29: YRFR | E29: =N50 -> 0.041666667
B30: ='Region-Time Slices'!$H$8&'Region-Time Slices'!J8 -> S04H04 | D30: YRFR | E30: =N51 -> 0.041666667
B31: ='Region-Time Slices'!$H$8&'Region-Time Slices'!J9 -> S04H05 | D31: YRFR | E31: =N52 -> 0.041666667
B32: ='Region-Time Slices'!$H$8&'Region-Time Slices'!J10 -> S04H06 | D32: YRFR | E32: =N53 -> 0.041666667
B33: ='Region-Time Slices'!$H$87&'Region-Time Slices'!J11
C43: Seasons | D43: N. of Days | E43: Fraction
B44: S01 | C44: 1 | D44: =365/4 -> 91.25 | E44: =D44/$D$48 -> 0.25
B45: S02 | C45: 2 | D45: =365/4 -> 91.25 | E45: =D45/$D$48 -> 0.25
B46: S03 | C46: 3 | D46: =365/4 -> 91.25 | E46: =D46/$D$48 -> 0.25
B47: S04 | C47: 4 | D47: =365/4 -> 91.25 | E47: =D47/$D$48 -> 0.25 | I47: Hours | K47: S1 | L47: S2 | M47: S3 | N47: S4
D48: =SUM(D44:D47) -> 365 | H48: H01 | I48: 4 | K48: =$I48/24*$E$44 -> 0.041666667 | L48: =$I48/24*$E$45 -> 0.041666667 | M48: =$I48/24*$E$46 -> 0.041666667 | N48: =$I48/24*$E$47 -> 0.041666667
F49: =SUM(C49:E49) -> 0 | H49: H02 | I49: 4 | K49: =$I49/24*$E$44 -> 0.041666667 | L49: =$I49/24*$E$45 -> 0.041666667 | M49: =$I49/24*$E$46 -> 0.041666667 | N49: =$I49/24*$E$47 -> 0.041666667
F50: =SUM(C50:E50) -> 0 | H50: H03 | I50: 4 | K50: =$I50/24*$E$44 -> 0.041666667 | L50: =$I50/24*$E$45 -> 0.041666667 | M50: =$I50/24*$E$46 -> 0.041666667 | N50: =$I50/24*$E$47 -> 0.041666667
H51: H04 | I51: 4 | K51: =$I51/24*$E$44 -> 0.041666667 | L51: =$I51/24*$E$45 -> 0.041666667 | M51: =$I51/24*$E$46 -> 0.041666667 | N51: =$I51/24*$E$47 -> 0.041666667
H52: H05 | I52: 4 | K52: =$I52/24*$E$44 -> 0.041666667 | L52: =$I52/24*$E$45 -> 0.041666667 | M52: =$I52/24*$E$46 -> 0.041666667 | N52: =$I52/24*$E$47 -> 0.041666667
...

Sheet Defaults
B2: ~Currencies | D2: ~DefUnits
B3: Currency | D3: Option | E3: PRI
B4: MEuro25 | D4: Process_ActUnit | E4: PJ
D5: Process_CapUnit | E5: Pja
D6: Commodity_Unit | E6: PJ
