Workbook
Name FID_1: [1]AGR_Fuels!$A$2

Sheet EB1
Z1: Default Units | AA1: Currency | AB1: Activity | AC1: Emissions
D2: COA | E2: GAS | F2: OIL | G2: DSL | H2: KER | I2: LPG | J2: GSL | K2: NAP | L2: HFO | M2: OPP | N2: NUC | O2: BIO | P2: HYD | Q2: WIN | R2: WIN | S2: WIN | T2: SOL | U2: SLU | V2: HET | W2: ELC | X2: TOT | AA2: M€2025 | AB2: PJ | AC2: kt
C3: REG1 | D3: Solid Fuels | E3: Natural Gas | F3: Crude oil | G3: Diesel oil | H3: Kerosenes | I3: LPG | J3: Motor spirit | K3: Naphtha | L3: Heavy Fuel Oil | M3: Other Petroleum Products | N3: Nuclear Energy | O3: Biomass | P3: Hydro power | Q3: Wind energy | R3: Wind onshore energy | S3: Wind offshore energy | T3: Solar energy | U3: Industrial Wastes | V3: Derived Heat | W3: Electricity | X3: Total
C4: CONVERSION
B5: ESC | C5: Energy Sector Consumption | D5: -37.4647 | E5: -317.192 | F5: 0 | G5: -16.284 | H5: -0.0215 | I5: -528.761 | J5: -164.508 | K5: -0.616 | L5: -205.88 | M5: 0 | N5: 0 | O5: -3.21225 | P5: 0 | Q5: 0 | T5: 0 | U5: -0.76 | V5: 0 | W5: 0 | X5: -1274.6994
B6: ELC | C6: Electricity Plants | D6: -6238.778 | E6: -2254.2176 | F6: 0 | G6: -30.1605 | H6: 0 | I6: -23.835 | J6: 0 | K6: 0 | L6: -524.78 | M6: -33.529 | N6: -4455 | O6: -527.25919 | P6: -502.66 | Q6: -263.8965 | T6: -68 | U6: -16.4745 | V6: 868.7795 | W6: 5790.5 | X6: -8279.3108
B7: HPL | C7: Heat Plants | D7: -104.9074 | E7: -120.5204 | F7: 0 | G7: -7.619 | H7: 0 | I7: -0.2335 | J7: 0 | K7: 0 | L7: -15.2 | M7: -1.772 | N7: 0 | O7: -105.15525 | P7: 0 | Q7: 0 | T7: 0 | U7: -0.7845 | V7: 329.3715 | W7: 0 | X7: -26.82055
B8: REF | C8: Petroleum Refineries | D8: 0 | E8: 0 | F8: -15868.23 | G8: 5701.34 | H8: 969.478 | I8: 1086.304 | J8: 3354.912 | K8: 970.288 | L8: 2285.102 | M8: 1299.945 | N8: 0 | O8: 0 | P8: 0 | Q8: 0 | T8: 0 | U8: 0 | V8: 0 | W8: 0 | X8: -200.8615
C9: Total Conversion | D9: =SUM(D5:D8) -> -6381.1501 | E9: =SUM(E5:E8) -> -2691.93 | F9: =SUM(F5:F8) -> -15868.23 | G9: =SUM(G5:G8) -> 5647.2765 | H9: =SUM(H5:H8) -> 969.4565 | I9: =SUM(I5:I8) -> 533.4745 | J9: =SUM(J5:J8) -> 3190.404 | K9: =SUM(K5:K8) -> 969.672 | ... Q9: =SUM(Q5:Q8) -> -263.8965 | T9: =SUM(T5:T8) -> -68 | U9: =SUM(U5:U8) -> -18.019 | V9: =SUM(V5:V8) -> 1198.151 | W9: =SUM(W5:W8) -> 5790.5 | X9: =SUM(X5:X8) -> -9781.6923
C12: Data used in the template to buld the model
C15: CO2 | D15: Nox | E15: VOC
B16: Emission by sector | C16: Carbon dioxide | D16: NOX | E16: VOC
B17: ELC | C17: 1

Sheet Intra_areas
B2: Solar | C2: Windon
B3: PARNU | C3: SOPITOOTSI
B4: TARTU | C4: SOPIPURTSE
B5: LVIRU | C5: OTHER
B6: IVIRU | C6: SAARE
B7: JARVA | C7: LVIRU
B8: JOGEVA | C8: HARJU
B9: HARJU | C9: LAANE
B10: POLVA | C10: IVIRU
B11: VALGA | C11: PARNU
B12: VILJANDI
B13: VORU
B14: SAARE
B15: RAPLA
B16: LAANE
B17: HIIU

Sheet Sector_Fuels_ELC
B1: Sector Name | C1: Commodity | D1: Description | E1: Deafult unit | F1: Currency | G1: Existing
B2: ='EB1'!B6 -> ELC | C2: ='EB1'!C6 -> Electricity Plants | D2: Sector Fuel | E2: ='EB1'!AB2 -> PJ | F2: ='EB1'!AA2 -> M€2025 | G2: E | J2: ~FI_Comm
J3: Csets | K3: Region | L3: CommName | M3: CommDesc | N3: Unit | O3: LimType | P3: CTSLvl | Q3: PeakTS | R3: Ctype
J4: *Commodity Set Membership | K4: Region Name | L4: Commodity Name | M4: Commodity Description | N4: Unit | O4: Sense of the Balance EQN. | P4: Timeslice Level | Q4: Peak Monitoring | R4: Electricity Indicator
J5: NRG | L5: =$B$2&'EB1'!$D$2 -> ELCCOA | M5: =$C$2&" "&'EB1'!$D$3 -> Electricity Plants Solid Fuels | N5: =$E$2 -> PJ
J6: NRG | L6: =$B$2&'EB1'!$E$2 -> ELCGAS | M6: =$C$2&" "&'EB1'!$E$3 -> Electricity Plants Natural Gas | N6: =$E$2 -> PJ
J7: NRG | L7: =$B$2&'EB1'!$F$2 -> ELCOIL | M7: =$C$2&" "&RIGHT('EB1'!$F$3,3) -> Electricity Plants oil | N7: =$E$2 -> PJ
J8: NRG | L8: =$B$2&'EB1'!$N$2 -> ELCNUC | M8: =$C$2&" "&'EB1'!$N$3 -> Electricity Plants Nuclear Energy | N8: =$E$2 -> PJ
J9: NRG | L9: =$B$2&'EB1'!$O$2 -> ELCBIO | M9: =$C$2&" "&'EB1'!$O$3 -> Electricity Plants Biomass | N9: =$E$2 -> PJ
J10: NRG | L10: =$B$2&'EB1'!$P$2 -> ELCHYD | M10: =$C$2&" "&'EB1'!$P$3 -> Electricity Plants Hydro power | N10: =$E$2 -> PJ
J11: NRG | L11: =$B$2&'EB1'!$Q$2 -> ELCWIN | M11: =$C$2&" "&'EB1'!$Q$3 -> Electricity Plants Wind energy | N11: =$E$2 -> PJ
J12: NRG | L12: ELCWON | M12: Electricity Plants Wind Onshore energy | N12: PJ
J13: NRG | L13: ELCWOF | M13: Electricity Plants Wind Offshore energy | N13: PJ
J14: NRG | L14: =$B$2&'EB1'!$T$2 -> ELCSOL | M14: =$C$2&" "&'EB1'!$T$3 -> Electricity Plants Solar energy | N14: =$E$2 -> PJ
J15: NRG | L15: ELCMSW | M15: Electricity Plants Municipal Waste | N15: PJ
J16: NRG | L16: ELCSHL | M16: Electricity Plants Oil Shale | N16: PJ
D18: ~FI_T | J18: ~FI_Process
B19: TechName | C19: Comm-IN | D19: Comm-OUT | E19: Share-I~UP | F19: STOCK | G19: EFF | H19: LIFE | J19: Sets | K19: Region | L19: TechName | M19: TechDesc | N19: Tact | O19: Tcap | P19: Tslvl | Q19: PrimaryCG | R19: Vintage
B20: *Technology Name | C20: Input Commodity | D20: Output Commodity | E20: Input Share | F20: Existing Installed Capacity | G20: Efficiency | H20: Lifetime | J20: *Process Set Membership | K20: Region Name | L20: Technology Name | M20: Technology Description | N20: Activity Unit | O20: Capacity Unit | P20: TimeSlice level of Process Activity | Q20: Primary Commodity Group | R20: Vintage Tracking
B21: *Units | F21: =F2&"a" -> M€2025a | H21: Years | J21: *
B22: =Sector_Fuels_ELC!L22 -> FTE-ELCCOA | C22: =RIGHT(D22,3) -> COA | D22: =L5 -> ELCCOA | G22: 1 | H22: 30 | J22: PRE | L22: ="FT"&$G$2&"-"&L5 -> FTE-ELCCOA | M22: =$D$2&" Technology"&" "&$G$1&" "&M5 -> Sector Fuel Technology Existing Electricity Plants Solid Fuels | N22: =$E$2 -> PJ | O22: =$E$2&"a" -> PJa
B23: =Sector_Fuels_ELC!L23 -> FTE-ELCGAS | C23: =RIGHT(D23,3) -> GAS | D23: =L6 -> ELCGAS | G23: 1 | H23: 30 | J23: PRE | L23: ="FT"&$G$2&"-"&L6 -> FTE-ELCGAS | M23: =$D$2&" Technology"&" "&$G$1&" "&M6 -> Sector Fuel Technology Existing Electricity Plants Natural Gas | N23: =$E$2 -> PJ | O23: =$E$2&"a" -> PJa
B24: =Sector_Fuels_ELC!L24 -> FTE-ELCOIL | C24: ='EB1'!G$2 -> DSL | D24: =L7 -> ELCOIL | E24: =-'EB1'!G$6/-SUM('EB1'!$G$6:$M$6) -> 0.049257355 | G24: 1 | H24: 30 | J24: PRE | L24: ="FT"&$G$2&"-"&L7 -> FTE-ELCOIL | M24: =$D$2&" Technology"&" "&$G$1&" "&M7 -> Sector Fuel Technology Existing Electricity Plants oil | N24: =$E$2 -> PJ | O24: =$E$2&"a" -> PJa
C25: ='EB1'!I$2 -> LPG | E25: =-'EB1'!I$6/-SUM('EB1'!$G$6:$M$6) -> 0.03892671 | J25: PRE | L25: ="FT"&$G$2&"-"&L8 -> FTE-ELCNUC | M25: =$D$2&" Technology"&" "&$G$1&" "&M8 -> Sector Fuel Technology Existing Electricity Plants Nuclear Energy | N25: =$E$2 -> PJ | O25: =$E$2&"a" -> PJa
C26: ='EB1'!L$2 -> HFO | E26: =-'EB1'!L$6/-SUM('EB1'!$G$6:$M$6) -> 0.85705723 | J26: PRE | L26: ="FT"&$G$2&"-"&L9 -> FTE-ELCBIO | M26: =$D$2&" Technology"&" "&$G$1&" "&M9 -> Sector Fuel Technology Existing Electricity Plants Biomass | N26: =$E$2 -> PJ | O26: =$E$2&"a" -> PJa
C27: ='EB1'!M$2 -> OPP | E27: =-'EB1'!M$6/-SUM('EB1'!$G$6:$M$6) -> 0.054758703 | J27: PRE | L27: ="FT"&$G$2&"-"&L10 -> FTE-ELCHYD | M27: =$D$2&" Technology"&" "&$G$1&" "&M10 -> Sector Fuel Technology Existing Electricity Plants Hydro power | N27: =$E$2 -> PJ | O27: =$E$2&"a" -> PJa
B28: =Sector_Fuels_ELC!L25 -> FTE-ELCNUC | C28: =RIGHT(D28,3) -> NUC | D28: =L8 -> ELCNUC | G28: 1 | H28: 30 | J28: PRE | L28: ="FT"&$G$2&"-"&L11 -> FTE-ELCWIN | M28: =$D$2&" Technology"&" "&$G$1&" "&M11 -> Sector Fuel Technology Existing Electricity Plants Wind energy | N28: =$E$2 -> PJ | O28: =$E$2&"a" -> PJa
B29: =Sector_Fuels_ELC!L26 -> FTE-ELCBIO | C29: =RIGHT(D29,3) -> BIO | D29: =L9 -> ELCBIO | G29: 1 | H29: 30 | J29: PRE | L29: ="FT"&$G$2&"-"&L12 -> FTE-ELCWON | M29: =$D$2&" Technology"&" "&$G$1&" "&M12 -> Sector Fuel Technology Existing Electricity Plants Wind Onshore energy | N29: =$E$2 -> PJ | O29: =$E$2&"a" -> PJa
B30: =Sector_Fuels_ELC!L27 -> FTE-ELCHYD | C30: =RIGHT(D30,3) -> HYD | D30: =L10 -> ELCHYD | G30: 1 | H30: 30 | J30: PRE | L30: ="FT"&$G$2&"-"&L13 -> FTE-ELCWOF | M30: =$D$2&" Technology"&" "&$G$1&" "&M13 -> Sector Fuel Technology Existing Electricity Plants Wind Offshore energy | N30: =$E$2 -> PJ | O30: =$E$2&"a" -> PJa
B31: =Sector_Fuels_ELC!L28 -> FTE-ELCWIN | C31: =RIGHT(D31,3) -> WIN | D31: =L11 -> ELCWIN | G31: 1 | H31: 30 | J31: PRE | L31: ="FT"&$G$2&"-"&L14 -> FTE-ELCSOL | M31: =$D$2&" Technology"&" "&$G$1&" "&M14 -> Sector Fuel Technology Existing Electricity Plants Solar energy | N31: =$E$2 -> PJ | O31: =$E$2&"a" -> PJa
B32: =Sector_Fuels_ELC!L29 -> FTE-ELCWON | C32: WIN | D32: =L12 -> ELCWON | G32: 1 | H32: 30 | J32: PRE | L32: ="FT"&$G$2&"-"&L15 -> FTE-ELCMSW | M32: =$D$2&" Technology"&" "&$G$1&" "&M15 -> Sector Fuel Technology Existing Electricity Plants Municipal Waste | N32: =$E$2 -> PJ | O32: =$E$2&"a" -> PJa
B33: =Sector_Fuels_ELC!L30 -> FTE-ELCWOF | C33: WIN | D33: =L13 -> ELCWOF | G33: 1 | H33: 30 | J33: PRE | L33: ="FT"&$G$2&"-"&L16 -> FTE-ELCSHL | M33: =$D$2&" Technology"&" "&$G$1&" "&M16 -> Sector Fuel Technology Existing Electricity Plants Oil Shale | N33: =$E$2 -> PJ | O33: =$E$2&"a" -> PJa
B34: =Sector_Fuels_ELC!L31 -> FTE-ELCSOL | C34: =RIGHT(D34,3) -> SOL | D34: =L14 -> ELCSOL | G34: 1 | H34: 30
B35: =Sector_Fuels_ELC!L32 -> FTE-ELCMSW | C35: =RIGHT(D35,3) -> MSW | D35: =L15 -> ELCMSW | G35: 1 | H35: 30
B36: =Sector_Fuels_ELC!L33 -> FTE-ELCSHL | C36: =RIGHT(D36,3) -> SHL | D36: =L16 -> ELCSHL | G36: 1 | H36: 30
C40: User inputs
C41: Linked to the Energy Balance

Sheet ELC
B1: Sector Name | C1: Description | D1: Type | E1: Activity Unit | F1: Capacity unit | G1: Currency Unit | H1: Existing
B2: ='EB1'!B6 -> ELC | C2: ='EB1'!C6 -> Electricity Plants | D2: Power Plants | E2: ='EB1'!AB2 -> PJ | F2: GW | G2: ='EB1'!AA2 -> M€2025 | H2: E | V2: ~FI_Comm
V3: Csets | W3: Region | X3: CommName | Y3: CommDesc | Z3: Unit | AA3: LimType | AB3: CTSLvl | AC3: PeakTS | AD3: Ctype
B4: Power Plant Type | C4: Thermal | D4: CHP | E4: Renewable | F4: Nuclear | V4: *Commodity Set Membership | W4: Region Name | X4: Commodity Name | Y4: Commodity Description | Z4: Unit | AA4: Sense of the Balance EQN. | AB4: Timeslice Level | AC4: Peak Monitoring | AD4: Electricity Indicator
B5: Code | C5: T | D5: C | E5: R | F5: N | L5: TWh2PJ | V5: NRG | X5: ELC | Y5: ='EB1'!$W$3 -> Electricity | Z5: TWh | AB5: DAYNITE | AD5: ELC
L6: 3.6 | V6: ENV | X6: =$B$2&'EB1'!$C$15 -> ELCCO2 | Y6: =$C$2&" "&'EB1'!$C$16 -> Electricity Plants Carbon dioxide | Z6: ='EB1'!$AC$2 -> kt
D8: ~FI_T | V8: ~FI_Process
B9: TechName | C9: Comm-IN | D9: Comm-OUT | E9: PASTI~1960 | F9: PASTI~1980 | G9: PASTI | H9: STOCK~2030 | I9: NCAP_BND~0 | J9: * | K9: EFF | L9: AFA | M9: INVCOST | N9: FIXOM | O9: VAROM | P9: LIFE | Q9: CAP2ACT | R9: Peak | T9: CALIBRATION | V9: Sets | W9: Region | X9: TechName | Y9: TechDesc | Z9: Tact | AA9: Tcap | AB9: Tslvl | AC9: PrimaryCG | AD9: Vintage
B10: *Technology Name | C10: Input Commodity | D10: Output Commodity | E10: Past Investment Capacity | F10: Past Investment Capacity | G10: Existing Installed Capacity | H10: Retirement Capacity | J10: EFF TWh | K10: Efficiency TWh -> PJ | L10: Utilisation Factor | M10: Invesctment Cost | N10: Fixed O&M Cost | O10: Variable O&M Cost | P10: Lifetime | Q10: Capacity to Activity Factor | R10: % contribution to PEAK | T10: Total Production | V10: *Process Set Membership | W10: Region Name | X10: Technology Name | Y10: Technology Description | Z10: Activity Unit | AA10: Capacity Unit | AB10: TimeSlice level of Process Activity | AC10: Primary Commodity Group | AD10: Vintage Tracking
B11: *Units | E11: =$F$2 -> GW | F11: =$F$2 -> GW | G11: =$F$2 -> GW | H11: =$F$2 -> GW | M11: =$G$2&"/"&$F$2 -> M€2025/GW | N11: =$G$2&"/"&$F$2 -> M€2025/GW | O11: M€2025/TWh | P11: Years | Q11: TWh/GW | T11: REG1 | V11: *
B12: =X12 -> ELCREHYD00 | C12: =$B$2&RIGHT(Sector_Fuels_ELC!L10,3) -> ELCHYD | D12: =$X$5 -> ELC | G12: 0.008 | I12: 2 | J12: 1 | K12: =J12*$L$6 -> 3.6 | L12: 0.5 | Q12: 8.76 | R12: 0.5 | T12: =(E12+F12)*$L12*$Q12 -> 0 | V12: ELE | X12: =$B$2&$E$5&$H$2&RIGHT(Sector_Fuels_ELC!$L$10,3)&"00" -> ELCREHYD00 | Y12: =$D$2&" "&$H$1&RIGHT(X12,2)&" - "&'EB1'!P3 -> Power Plants Existing00 - Hydro power | Z12: TWh | AA12: =$F$2 -> GW | AB12: DAYNITE
B13: =X13 -> ELCRESOL_PARNU00 | C13: =$B$2&RIGHT(Sector_Fuels_ELC!L14,3) -> ELCSOL | D13: =$X$5 -> ELC | G13: 0.242 | I13: 2 | J13: 1 | K13: =J13*$L$6 -> 3.6 | L13: 0.3 | M13: 1018 | N13: 16.06404 | O13: 0 | P13: 35 | Q13: 8.76 | R13: 0.14618542 | V13: ELE | X13: =$B$2&$E$5&$H$2&RIGHT(Sector_Fuels_ELC!$L$14,3)&"_"&Intra_areas!B3&"00" -> ELCRESOL_PARNU00 | Y13: =$D$2&" "&$H$1&RIGHT(X13,2)&" in "&Intra_areas!B3&" - "&'EB1'!$T$3 -> Power Plants Existing00 in PARNU - Solar energy | Z13: TWh | AA13: GW | AB13: DAYNITE
B14: =X14 -> ELCRESOL_TARTU00 | C14: =$B$2&RIGHT(Sector_Fuels_ELC!L14,3) -> ELCSOL | D14: =$X$5 -> ELC | G14: 0.108 | I14: 2 | J14: 1 | K14: =J14*$L$6 -> 3.6 | L14: 0.3 | M14: 1018 | N14: 16.06404 | O14: 0 | P14: 35 | Q14: 8.76 | R14: 0.14618542 | V14: ELE | X14: =$B$2&$E$5&$H$2&RIGHT(Sector_Fuels_ELC!$L$14,3)&"_"&Intra_areas!B4&"00" -> ELCRESOL_TARTU00 | Y14: =$D$2&" "&$H$1&RIGHT(X14,2)&" in "&Intra_areas!B4&" - "&'EB1'!$T$3 -> Power Plants Existing00 in TARTU - Solar energy | Z14: TWh | AA14: GW | AB14: DAYNITE
B15: =X15 -> ELCRESOL_LVIRU00 | C15: =$B$2&RIGHT(Sector_Fuels_ELC!L14,3) -> ELCSOL | D15: =$X$5 -> ELC | G15: 0.132 | I15: 2 | J15: 1 | K15: =J15*$L$6 -> 3.6 | L15: 0.3 | M15: 1018 | N15: 16.06404 | O15: 0 | P15: 35 | Q15: 8.76 | R15: 0.14867925 | V15: ELE | X15: =$B$2&$E$5&$H$2&RIGHT(Sector_Fuels_ELC!$L$14,3)&"_"&Intra_areas!B5&"00" -> ELCRESOL_LVIRU00 | Y15: =$D$2&" "&$H$1&RIGHT(X15,2)&" in "&Intra_areas!B5&" - "&'EB1'!$T$3 -> Power Plants Existing00 in LVIRU - Solar energy | Z15: TWh | AA15: GW | AB15: DAYNITE
B16: =X16 -> ELCRESOL_IVIRU00 | C16: =$B$2&RIGHT(Sector_Fuels_ELC!L14,3) -> ELCSOL | D16: =$X$5 -> ELC | G16: 0.078 | I16: 2 | J16: 1 | K16: =J16*$L$6 -> 3.6 | L16: 0.3 | M16: 1018 | N16: 16.06404 | O16: 0 | P16: 35 | Q16: 8.76 | R16: 0.1470126 | V16: ELE | X16: =$B$2&$E$5&$H$2&RIGHT(Sector_Fuels_ELC!$L$14,3)&"_"&Intra_areas!B6&"00" -> ELCRESOL_IVIRU00 | Y16: =$D$2&" "&$H$1&RIGHT(X16,2)&" in "&Intra_areas!B6&" - "&'EB1'!$T$3 -> Power Plants Existing00 in IVIRU - Solar energy | Z16: TWh | AA16: GW | AB16: DAYNITE
B17: =X17 -> ELCRESOL_JARVA00 | C17: =$B$2&RIGHT(Sector_Fuels_ELC!L14,3) -> ELCSOL | D17: =$X$5 -> ELC | G17: 0.075 | I17: 2 | J17: 1 | K17: =J17*$L$6 -> 3.6 | L17: 0.3 | M17: 1018 | N17: 16.06404 | O17: 0 | P17: 35 | Q17: 8.76 | R17: 0.1530986 | V17: ELE | X17: =$B$2&$E$5&$H$2&RIGHT(Sector_Fuels_ELC!$L$14,3)&"_"&Intra_areas!B7&"00" -> ELCRESOL_JARVA00 | Y17: =$D$2&" "&$H$1&RIGHT(X17,2)&" in "&Intra_areas!B7&" - "&'EB1'!$T$3 -> Power Plants Existing00 in JARVA - Solar energy | Z17: TWh | AA17: GW | AB17: DAYNITE
B18: =X18 -> ELCRESOL_JOGEVA00 | C18: =$B$2&RIGHT(Sector_Fuels_ELC!L14,3) -> ELCSOL | D18: =$X$5 -> ELC | G18: 0.047 | I18: 2 | J18: 1 | K18: =J18*$L$6 -> 3.6 | L18: 0.3 | M18: 1018 | N18: 16.06404 | O18: 0 | P18: 35 | Q18: 8.76 | R18: 0.1530986 | V18: ELE | X18: =$B$2&$E$5&$H$2&RIGHT(Sector_Fuels_ELC!$L$14,3)&"_"&Intra_areas!B8&"00" -> ELCRESOL_JOGEVA00 | Y18: =$D$2&" "&$H$1&RIGHT(X18,2)&" in "&Intra_areas!B8&" - "&'EB1'!$T$3 -> Power Plants Existing00 in JOGEVA - Solar energy | Z18: TWh | AA18: GW | AB18: DAYNITE
B19: =X19 -> ELCRESOL_HARJU00 | C19: =$B$2&RIGHT(Sector_Fuels_ELC!L14,3) -> ELCSOL | D19: =$X$5 -> ELC | G19: 0.04 | I19: 2 | J19: 1 | K19: =J19*$L$6 -> 3.6 | L19: 0.3 | M19: 1018 | N19: 16.06404 | O19: 0 | P19: 35 | Q19: 8.76 | R19: 0.15619561 | V19: ELE | X19: =$B$2&$E$5&$H$2&RIGHT(Sector_Fuels_ELC!$L$14,3)&"_"&Intra_areas!B9&"00" -> ELCRESOL_HARJU00 | Y19: =$D$2&" "&$H$1&RIGHT(X19,2)&" in "&Intra_areas!B9&" - "&'EB1'!$T$3 -> Power Plants Existing00 in HARJU - Solar energy | Z19: TWh | AA19: GW | AB19: DAYNITE
B20: =X20 -> ELCRESOL_POLVA00 | C20: =$B$2&RIGHT(Sector_Fuels_ELC!L14,3) -> ELCSOL | D20: =$X$5 -> ELC | G20: 0.242 | I20: 2 | J20: 1 | K20: =J20*$L$6 -> 3.6 | L20: 0.3 | M20: 1018 | N20: 16.06404 | O20: 0 | P20: 35 | Q20: 8.76 | R20: 0.1453731 | V20: ELE | X20: =$B$2&$E$5&$H$2&RIGHT(Sector_Fuels_ELC!$L$14,3)&"_"&Intra_areas!B10&"00" -> ELCRESOL_POLVA00 | Y20: =$D$2&" "&$H$1&RIGHT(X20,2)&" in "&Intra_areas!B10&" - "&'EB1'!$T$3 -> Power Plants Existing00 in POLVA - Solar energy | Z20: TWh | AA20: GW | AB20: DAYNITE
B21: =X21 -> ELCRESOL_VALGA00 | C21: =$B$2&RIGHT(Sector_Fuels_ELC!L14,3) -> ELCSOL | D21: =$X$5 -> ELC | G21: 0.043 | I21: 2 | J21: 1 | K21: =J21*$L$6 -> 3.6 | L21: 0.3 | M21: 1018 | N21: 16.06404 | O21: 0 | P21: 35 | Q21: 8.76 | R21: 0.14763874 | V21: ELE | X21: =$B$2&$E$5&$H$2&RIGHT(Sector_Fuels_ELC!$L$14,3)&"_"&Intra_areas!B11&"00" -> ELCRESOL_VALGA00 | Y21: =$D$2&" "&$H$1&RIGHT(X21,2)&" in "&Intra_areas!B11&" - "&'EB1'!$T$3 -> Power Plants Existing00 in VALGA - Solar energy | Z21: TWh | AA21: GW | AB21: DAYNITE
B22: =X22 -> ELCRESOL_VILJANDI00 | C22: =$B$2&RIGHT(Sector_Fuels_ELC!L14,3) -> ELCSOL | D22: =$X$5 -> ELC | G22: 0.08 | I22: 2 | J22: 1 | K22: =J22*$L$6 -> 3.6 | L22: 0.3 | M22: 1018 | N22: 16.06404 | O22: 0 | P22: 35 | Q22: 8.76 | R22: 0.15326283 | V22: ELE | X22: =$B$2&$E$5&$H$2&RIGHT(Sector_Fuels_ELC!$L$14,3)&"_"&Intra_areas!B12&"00" -> ELCRESOL_VILJANDI00 | Y22: =$D$2&" "&$H$1&RIGHT(X22,2)&" in "&Intra_areas!B12&" - "&'EB1'!$T$3 -> Power Plants Existing00 in VILJANDI - Solar energy | Z22: TWh | AA22: GW | AB22: DAYNITE
B23: =X23 -> ELCRESOL_VORU00 | C23: =$B$2&RIGHT(Sector_Fuels_ELC!L14,3) -> ELCSOL | D23: =$X$5 -> ELC | G23: 0.035 | I23: 2 | J23: 1 | K23: =J23*$L$6 -> 3.6 | L23: 0.3 | M23: 1019 | N23: 16.07982 | O23: 0 | P23: 35 | Q23: 8.76 | R23: 0.14618542 | V23: ELE | X23: =$B$2&$E$5&$H$2&RIGHT(Sector_Fuels_ELC!$L$14,3)&"_"&Intra_areas!B13&"00" -> ELCRESOL_VORU00 | Y23: =$D$2&" "&$H$1&RIGHT(X23,2)&" in "&Intra_areas!B13&" - "&'EB1'!$T$3 -> Power Plants Existing00 in VORU - Solar energy | Z23: TWh | AA23: GW | AB23: DAYNITE
B24: =X24 -> ELCRESOL_SAARE00 | C24: =$B$2&RIGHT(Sector_Fuels_ELC!L14,3) -> ELCSOL | D24: =$X$5 -> ELC | G24: 0.031 | I24: 2 | J24: 1 | K24: =J24*$L$6 -> 3.6 | L24: 0.3 | M24: 1020 | N24: 16.0956 | O24: 0 | P24: 35 | Q24: 8.76 | R24: 0.14618542 | V24: ELE | X24: =$B$2&$E$5&$H$2&RIGHT(Sector_Fuels_ELC!$L$14,3)&"_"&Intra_areas!B14&"00" -> ELCRESOL_SAARE00 | Y24: =$D$2&" "&$H$1&RIGHT(X24,2)&" in "&Intra_areas!B14&" - "&'EB1'!$T$3 -> Power Plants Existing00 in SAARE - Solar energy | Z24: TWh | AA24: GW | AB24: DAYNITE
B25: =X25 -> ELCRESOL_RAPLA00 | C25: =$B$2&RIGHT(Sector_Fuels_ELC!L14,3) -> ELCSOL | D25: =$X$5 -> ELC | G25: 0.029 | I25: 2 | J25: 1 | K25: =J25*$L$6 -> 3.6 | L25: 0.3 | M25: 1021 | N25: 16.11138 | O25: 0 | P25: 35 | Q25: 8.76 | R25: 0.14618542 | V25: ELE | X25: =$B$2&$E$5&$H$2&RIGHT(Sector_Fuels_ELC!$L$14,3)&"_"&Intra_areas!B15&"00" -> ELCRESOL_RAPLA00 | Y25: =$D$2&" "&$H$1&RIGHT(X25,2)&" in "&Intra_areas!B15&" - "&'EB1'!$T$3 -> Power Plants Existing00 in RAPLA - Solar energy | Z25: TWh | AA25: GW | AB25: DAYNITE
B26: =X26 -> ELCRESOL_LAANE00 | C26: =$B$2&RIGHT(Sector_Fuels_ELC!L14,3) -> ELCSOL | D26: =$X$5 -> ELC | G26: 0.01 | I26: 2 | J26: 1 | K26: =J26*$L$6 -> 3.6 | L26: 0.3 | M26: 1022 | N26: 16.12716 | O26: 0 | P26: 35 | Q26: 8.76 | R26: 0.14618542 | V26: ELE | X26: =$B$2&$E$5&$H$2&RIGHT(Sector_Fuels_ELC!$L$14,3)&"_"&Intra_areas!B16&"00" -> ELCRESOL_LAANE00 | Y26: =$D$2&" "&$H$1&RIGHT(X26,2)&" in "&Intra_areas!B16&" - "&'EB1'!$T$3 -> Power Plants Existing00 in LAANE - Solar energy | Z26: TWh | AA26: GW | AB26: DAYNITE
B27: =X27 -> ELCRESOL_HIIU00 | C27: =$B$2&RIGHT(Sector_Fuels_ELC!L14,3) -> ELCSOL | D27: =$X$5 -> ELC | G27: 0.005 | I27: 2 | J27: 1 | K27: =J27*$L$6 -> 3.6 | L27: 0.3 | M27: 1023 | N27: 16.14294 | O27: 0 | P27: 35 | Q27: 8.76 | R27: 0.14618542 | V27: ELE | X27: =$B$2&$E$5&$H$2&RIGHT(Sector_Fuels_ELC!$L$14,3)&"_"&Intra_areas!B17&"00" -> ELCRESOL_HIIU00 | Y27: =$D$2&" "&$H$1&RIGHT(X27,2)&" in "&Intra_areas!B17&" - "&'EB1'!$T$3 -> Power Plants Existing00 in HIIU - Solar energy | Z27: TWh | AA27: GW | AB27: DAYNITE
B28: =X28 -> ELCREWON_SOPITOOTSI00 | C28: =$B$2&RIGHT(Sector_Fuels_ELC!$L$12,3) -> ELCWON | D28: =$X$5 -> ELC | G28: 0.0797 | I28: 2 | J28: 1 | K28: =J28*$L$6 -> 3.6 | L28: 0.3 | M28: 1494.4631 | N28: 18.701711 | O28: 2.0037 | P28: 27 | Q28: 8.76 | R28: 0.4 | V28: ELE | X28: =$B$2&$E$5&$H$2&RIGHT(Sector_Fuels_ELC!$L$12,3)&"_"&Intra_areas!C3&"00" -> ELCREWON_SOPITOOTSI00 | Y28: =$D$2&" "&$H$1&RIGHT(X28,2)&" in "&Intra_areas!C3&" - "&'EB1'!$R$3 -> Power Plants Existing00 in SOPITOOTSI - Wind onshore energy | Z28: TWh | AA28: GW | AB28: DAYNITE
B29: =X29 -> ELCREWON_SOPIPURTSE00 | C29: =$B$2&RIGHT(Sector_Fuels_ELC!$L$12,3) -> ELCWON | D29: =$X$5 -> ELC | G29: 0.1752 | I29: 2 | J29: 1 | K29: =J29*$L$6 -> 3.6 | L29: 0.3 | M29: 1494.4631 | N29: 18.701711 | O29: 2.0037 | P29: 27 | Q29: 8.76 | R29: 0.4 | V29: ELE | X29: =$B$2&$E$5&$H$2&RIGHT(Sector_Fuels_ELC!$L$12,3)&"_"&Intra_areas!C4&"00" -> ELCREWON_SOPIPURTSE00 | Y29: =$D$2&" "&$H$1&RIGHT(X29,2)&" in "&Intra_areas!C4&" - "&'EB1'!$R$3 -> Power Plants Existing00 in SOPIPURTSE - Wind onshore energy | Z29: TWh | AA29: GW | AB29: DAYNITE
B30: =X30 -> ELCREWON_OTHER00 | C30: =$B$2&RIGHT(Sector_Fuels_ELC!$L$12,3) -> ELCWON | D30: =$X$5 -> ELC | G30: 0.0813 | I30: 2 | J30: 1 | K30: =J30*$L$6 -> 3.6 | L30: 0.3 | M30: 1494.4631 | N30: 18.701711 | O30: 2.0037 | P30: 27 | Q30: 8.76 | R30: 0.4 | V30: ELE | X30: =$B$2&$E$5&$H$2&RIGHT(Sector_Fuels_ELC!$L$12,3)&"_"&Intra_areas!C5&"00" -> ELCREWON_OTHER00 | Y30: =$D$2&" "&$H$1&RIGHT(X30,2)&" in "&Intra_areas!C5&" - "&'EB1'!$R$3 -> Power Plants Existing00 in OTHER - Wind onshore energy | Z30: TWh | AA30: GW | AB30: DAYNITE
B31: =X31 -> ELCREWON_SAARE00 | C31: =$B$2&RIGHT(Sector_Fuels_ELC!$L$12,3) -> ELCWON | D31: =$X$5 -> ELC | G31: 0.016 | I31: 2 | J31: 1 | K31: =J31*$L$6 -> 3.6 | L31: 0.3 | M31: 1494.4631 | N31: 18.701711 | O31: 2.0037 | P31: 27 | Q31: 8.76 | R31: 0.4 | V31: ELE | X31: =$B$2&$E$5&$H$2&RIGHT(Sector_Fuels_ELC!$L$12,3)&"_"&Intra_areas!C6&"00" -> ELCREWON_SAARE00 | Y31: =$D$2&" "&$H$1&RIGHT(X31,2)&" in "&Intra_areas!C6&" - "&'EB1'!$R$3 -> Power Plants Existing00 in SAARE - Wind onshore energy | Z31: TWh | AA31: GW | AB31: DAYNITE
B32: =X32 -> ELCREWON_LVIRU00 | C32: =$B$2&RIGHT(Sector_Fuels_ELC!$L$12,3) -> ELCWON | D32: =$X$5 -> ELC | G32: 0.0327 | I32: 2 | J32: 1 | K32: =J32*$L$6 -> 3.6 | L32: 0.3 | M32: 1494.4631 | N32: 18.701711 | O32: 2.0037 | P32: 27 | Q32: 8.76 | R32: 0.4 | V32: ELE | X32: =$B$2&$E$5&$H$2&RIGHT(Sector_Fuels_ELC!$L$12,3)&"_"&Intra_areas!C7&"00" -> ELCREWON_LVIRU00 | Y32: =$D$2&" "&$H$1&RIGHT(X32,2)&" in "&Intra_areas!C7&" - "&'EB1'!$R$3 -> Power Plants Existing00 in LVIRU - Wind onshore energy | Z32: TWh | AA32: GW | AB32: DAYNITE
B33: =X33 -> ELCREWON_HARJU00 | C33: =$B$2&RIGHT(Sector_Fuels_ELC!$L$12,3) -> ELCWON | D33: =$X$5 -> ELC | G33: 0.0634 | I33: 2 | J33: 1 | K33: =J33*$L$6 -> 3.6 | L33: 0.3 | M33: 1494.4631 | N33: 18.701711 | O33: 2.0037 | P33: 27 | Q33: 8.76 | R33: 0.4 | V33: ELE | X33: =$B$2&$E$5&$H$2&RIGHT(Sector_Fuels_ELC!$L$12,3)&"_"&Intra_areas!C8&"00" -> ELCREWON_HARJU00 | Y33: =$D$2&" "&$H$1&RIGHT(X33,2)&" in "&Intra_areas!C8&" - "&'EB1'!$R$3 -> Power Plants Existing00 in HARJU - Wind onshore energy | Z33: TWh | AA33: GW | AB33: DAYNITE
B34: =X34 -> ELCREWON_LAANE00 | C34: =$B$2&RIGHT(Sector_Fuels_ELC!$L$12,3) -> ELCWON | D34: =$X$5 -> ELC | G34: 0.06 | I34: 2 | J34: 1 | K34: =J34*$L$6 -> 3.6 | L34: 0.3 | M34: 1494.4631 | N34: 18.701711 | O34: 2.0037 | P34: 27 | Q34: 8.76 | R34: 0.4 | V34: ELE | X34: =$B$2&$E$5&$H$2&RIGHT(Sector_Fuels_ELC!$L$12,3)&"_"&Intra_areas!C9&"00" -> ELCREWON_LAANE00 | Y34: =$D$2&" "&$H$1&RIGHT(X34,2)&" in "&Intra_areas!C9&" - "&'EB1'!$R$3 -> Power Plants Existing00 in LAANE - Wind onshore energy | Z34: TWh | AA34: GW | AB34: DAYNITE
B35: =X35 -> ELCREWON_IVIRU00 | C35: =$B$2&RIGHT(Sector_Fuels_ELC!$L$12,3) -> ELCWON | D35: =$X$5 -> ELC | G35: 0.082 | I35: 2 | J35: 1 | K35: =J35*$L$6 -> 3.6 | L35: 0.3 | M35: 1494.4631 | N35: 18.701711 | O35: 2.0037 | P35: 27 | Q35: 8.76 | R35: 0.4 | V35: ELE | X35: =$B$2&$E$5&$H$2&RIGHT(Sector_Fuels_ELC!$L$12,3)&"_"&Intra_areas!C10&"00" -> ELCREWON_IVIRU00 | Y35: =$D$2&" "&$H$1&RIGHT(X35,2)&" in "&Intra_areas!C10&" - "&'EB1'!$R$3 -> Power Plants Existing00 in IVIRU - Wind onshore energy | Z35: TWh | AA35: GW | AB35: DAYNITE
B36: =X36 -> ELCREWON_PARNU00 | C36: =$B$2&RIGHT(Sector_Fuels_ELC!$L$12,3) -> ELCWON | D36: =$X$5 -> ELC | G36: 0.1036 | I36: 2 | J36: 1 | K36: =J36*$L$6 -> 3.6 | L36: 0.3 | M36: 1494.4631 | N36: 18.701711 | O36: 2.0037 | P36: 27 | Q36: 8.76 | R36: 0.4 | V36: ELE | X36: =$B$2&$E$5&$H$2&RIGHT(Sector_Fuels_ELC!$L$12,3)&"_"&Intra_areas!C11&"00" -> ELCREWON_PARNU00 | Y36: =$D$2&" "&$H$1&RIGHT(X36,2)&" in "&Intra_areas!C11&" - "&'EB1'!$R$3 -> Power Plants Existing00 in PARNU - Wind onshore energy | Z36: TWh | AA36: GW | AB36: DAYNITE
B37: =X37 -> ELCREMSW_IRU00 | C37: =$B$2&RIGHT(Sector_Fuels_ELC!L15,3) -> ELCMSW | D37: =$X$5 -> ELC | G37: 0.017 | I37: 2 | J37: 0.56 | K37: =J37*$L$6 -> 2.016 | L37: 0.9 | M37: 1175.5067 | N37: 160.21635 | O37: 5.8775 | P37: 40 | Q37: 8.76 | R37: 1 | V37: ELE | X37: =$B$2&$E$5&$H$2&RIGHT(Sector_Fuels_ELC!L15,3)&"_IRU"&"00" -> ELCREMSW_IRU00 | Y37: =$D$2&" "&$H$1&RIGHT(X37,2)&" Iru Power plant - Municipal waste" -> Power Plants Existing00 Iru Power plant - Municipal waste | Z37: TWh | AA37: GW | AB37: DAYNITE
B38: =X38 -> ELCTESHL_EESTI00 | C38: =$B$2&RIGHT(Sector_Fuels_ELC!$L$16,3) -> ELCSHL | D38: =$X$5 -> ELC | G38: 0.77 | I38: 2 | J38: 0.33 | K38: =J38*$L$6 -> 1.188 | L38: 0.95 | M38: 4812.0244 | N38: 63.03752 | O38: 4.1005 | P38: 10 | Q38: 8.76 | R38: 1 | V38: ELE | X38: =$B$2&$C$5&$H$2&RIGHT(Sector_Fuels_ELC!$L$16,3)&"_EESTI00" -> ELCTESHL_EESTI00 | Y38: =$D$2&" "&$H$1&RIGHT(X38,2)&" Eesti Power plant - Oil Shale" -> Power Plants Existing00 Eesti Power plant - Oil Shale | Z38: TWh | AA38: GW | AB38: DAYNITE
B39: =X39 -> ELCTESHL_AUVERE00 | C39: =$B$2&RIGHT(Sector_Fuels_ELC!$L$16,3) -> ELCSHL | D39: =$X$5 -> ELC | G39: 0.26 | I39: 2 | J39: 0.33 | K39: =J39*$L$6 -> 1.188 | L39: 0.95 | M39: 4812.0244 | N39: 63.03752 | O39: 4.1005 | P39: 10 | Q39: 8.76 | R39: 1 | V39: ELE | X39: =$B$2&$C$5&$H$2&RIGHT(Sector_Fuels_ELC!$L$16,3)&"_AUVERE00" -> ELCTESHL_AUVERE00 | Y39: =$D$2&" "&$H$1&RIGHT(X39,2)&" Auvere Power plant - Oil Shale" -> Power Plants Existing00 Auvere Power plant - Oil Shale | Z39: TWh | AA39: GW | AB39: DAYNITE
B40: =X40 -> ELCTESHL_ENEFIT00 | C40: =$B$2&RIGHT(Sector_Fuels_ELC!$L$16,3) -> ELCSHL | D40: =$X$5 -> ELC | G40: 0.01 | I40: 2 | J40: 0.33 | K40: =J40*$L$6 -> 1.188 | L40: 0.95 | M40: 4812.0244 | N40: 63.03752 | O40: 4.1005 | P40: 10 | Q40: 8.76 | R40: 1 | V40: ELE | X40: =$B$2&$C$5&$H$2&RIGHT(Sector_Fuels_ELC!$L$16,3)&"_ENEFIT00" -> ELCTESHL_ENEFIT00 | Y40: =$D$2&" "&$H$1&RIGHT(X40,2)&" Eenefit Power plant - Oil Shale" -> Power Plants Existing00 Eenefit Power plant - Oil Shale | Z40: TWh | AA40: GW | AB40: DAYNITE
B41: =X41 -> ELCTESHL_BALTI00 | C41: =$B$2&RIGHT(Sector_Fuels_ELC!$L$16,3) -> ELCSHL | D41: =$X$5 -> ELC | G41: 0.185 | I41: 2 | J41: 0.33 | K41: =J41*$L$6 -> 1.188 | L41: 0.95 | M41: 4812.0244 | N41: 63.03752 | O41: 4.1005 | P41: 10 | Q41: 8.76 | R41: 1 | V41: ELE | X41: =$B$2&$C$5&$H$2&RIGHT(Sector_Fuels_ELC!$L$16,3)&"_BALTI00" -> ELCTESHL_BALTI00 | Y41: =$D$2&" "&$H$1&RIGHT(X41,2)&" Balti Power plant - Oil Shale" -> Power Plants Existing00 Balti Power plant - Oil Shale | Z41: TWh | AA41: GW | AB41: DAYNITE
...

Sheet CHP
B1: Sector Name | C1: Description | D1: Type | E1: Activity Unit | F1: Capacity unit | G1: Currency Unit | H1: Existing
B2: ='EB1'!B6 -> ELC | C2: ='EB1'!C6 -> Electricity Plants | D2: Power Plants | E2: ='EB1'!AB2 -> PJ | F2: GW | G2: ='EB1'!AA2 -> M€2025 | H2: E
B4: Power Plant Type | C4: Thermal | D4: CHP | E4: Renewable | F4: Nuclear
B5: Code | C5: T | D5: C | E5: R | F5: N
D8: ~FI_T | Q8: ~FI_Process
B9: TechName | C9: Comm-IN | D9: Comm-OUT | E9: STOCK | F9: STOCK~2030 | G9: EFF | H9: AFA | I9: INVCOST | J9: FIXOM | K9: VAROM | L9: LIFE | M9: CAP2ACT | N9: Peak | Q9: Sets | R9: Region | S9: TechName | T9: TechDesc | U9: Tact | V9: Tcap | W9: Tslvl | X9: PrimaryCG | Y9: Vintage
B10: *Technology Name | C10: Input Commodity | D10: Output Commodity | E10: Existing Installed Capacity | F10: Retirement Capacity | G10: Efficiency | H10: Utilisation Factor | I10: Invesctment Cost | J10: Fixed O&M Cost | K10: Variable O&M Cost | L10: Lifetime | M10: Capacity to Activity Factor | N10: % contribution to PEAK | Q10: *Process Set Membership | R10: Region Name | S10: Technology Name | T10: Technology Description | U10: Activity Unit | V10: Capacity Unit | W10: TimeSlice level of Process Activity | X10: Primary Commodity Group | Y10: Vintage Tracking
B11: *Units | E11: =$F$2 -> GW | F11: =$F$2 -> GW | I11: =$G$2&"/"&$F$2 -> M€2025/GW | J11: =$G$2&"/"&$F$2 -> M€2025/GW | K11: =$G$2&"/"&$E$2 -> M€2025/PJ | L11: Years | M11: TWh/GW | Q11: *
B12: =S12 -> ELCCEBIO_OSULA00 | C12: =$B$2&RIGHT(Sector_Fuels_ELC!$L$9,3) -> ELCBIO | D12: =ELC!$X$5 -> ELC | E12: 0.01 | G12: 0.29 | H12: 0.95 | I12: 4516.7133 | J12: 162.96753 | K12: 2.8138 | L12: 40 | M12: 8.76 | N12: 1 | Q12: ELE | S12: =$B$2&$D$5&$H$2&RIGHT(Sector_Fuels_ELC!$L$9,3)&"_OSULA00" -> ELCCEBIO_OSULA00 | T12: =$D$2&" "&$H$1&RIGHT(S12,2)&" Osula CHP - "&'EB1'!$O$3 -> Power Plants Existing00 Osula CHP - Biomass | U12: TWh | V12: GW | W12: DAYNITE
B13: =S13 -> ELCCEBIO_MUSTAMAE00 | C13: =$B$2&RIGHT(Sector_Fuels_ELC!$L$9,3) -> ELCBIO | D13: =ELC!$X$5 -> ELC | E13: 0.0093 | G13: 0.29 | H13: 0.95 | I13: 4516.7133 | J13: 162.96753 | K13: 2.8138 | L13: 40 | M13: 8.76 | N13: 1 | Q13: ELE | S13: =$B$2&$D$5&$H$2&RIGHT(Sector_Fuels_ELC!$L$9,3)&"_MUSTAMAE00" -> ELCCEBIO_MUSTAMAE00 | T13: =$D$2&" "&$H$1&RIGHT(S13,2)&" Mustamae CHP - "&'EB1'!$O$3 -> Power Plants Existing00 Mustamae CHP - Biomass | U13: TWh | V13: GW | W13: DAYNITE
B14: =S14 -> ELCCEBIO_SILLAMAE100 | C14: =$B$2&RIGHT(Sector_Fuels_ELC!$L$9,3) -> ELCBIO | D14: =ELC!$X$5 -> ELC | E14: 0.0071 | G14: 0.29 | H14: 0.95 | I14: 4516.7133 | J14: 162.96753 | K14: 2.8138 | L14: 72 | M14: 8.76 | N14: 1 | Q14: ELE | S14: =$B$2&$D$5&$H$2&RIGHT(Sector_Fuels_ELC!$L$9,3)&"_SILLAMAE100" -> ELCCEBIO_SILLAMAE100 | T14: =$D$2&" "&$H$1&RIGHT(S14,2)&" Sillamae 1 CHP - "&'EB1'!$O$3 -> Power Plants Existing00 Sillamae 1 CHP - Biomass | U14: TWh | V14: GW | W14: DAYNITE
B15: =S15 -> ELCCEGAS_SILLAMAE200 | C15: =$B$2&RIGHT(Sector_Fuels_ELC!$L$6,3) -> ELCGAS | D15: =ELC!$X$5 -> ELC | E15: 0.0058 | G15: 0.56 | H15: 0.95 | I15: 1175.5067 | J15: 39.138496 | K15: 5.8775 | L15: 40 | M15: 8.76 | N15: 1 | Q15: ELE | S15: =$B$2&$D$5&$H$2&RIGHT(Sector_Fuels_ELC!$L$6,3)&"_SILLAMAE200" -> ELCCEGAS_SILLAMAE200 | T15: =$D$2&" "&$H$1&RIGHT(S15,2)&" Sillamae 2 CHP - "&'EB1'!$E$3 -> Power Plants Existing00 Sillamae 2 CHP - Natural Gas | U15: TWh | V15: GW | W15: DAYNITE
B16: =S16 -> ELCCEBIO_HELME00 | C16: =$B$2&RIGHT(Sector_Fuels_ELC!$L$9,3) -> ELCBIO | D16: =ELC!$X$5 -> ELC | E16: 0.0065 | G16: 0.29 | H16: 0.95 | I16: 4516.7133 | J16: 162.96753 | K16: 2.8138 | L16: 40 | M16: 8.76 | N16: 1 | Q16: ELE | S16: =$B$2&$D$5&$H$2&RIGHT(Sector_Fuels_ELC!$L$9,3)&"_HELME00" -> ELCCEBIO_HELME00 | T16: =$D$2&" "&$H$1&RIGHT(S16,2)&" Helme CHP - "&'EB1'!$O$3 -> Power Plants Existing00 Helme CHP - Biomass | U16: TWh | V16: GW | W16: DAYNITE
B17: =S17 -> ELCCEBIO_KURESSAARE00 | C17: =$B$2&RIGHT(Sector_Fuels_ELC!$L$9,3) -> ELCBIO | D17: =ELC!$X$5 -> ELC | E17: 0.0018 | G17: 0.29 | H17: 0.95 | I17: 4516.7133 | J17: 162.96753 | K17: 2.8138 | L17: 40 | M17: 8.76 | N17: 1 | Q17: ELE | S17: =$B$2&$D$5&$H$2&RIGHT(Sector_Fuels_ELC!$L$9,3)&"_KURESSAARE00" -> ELCCEBIO_KURESSAARE00 | T17: =$D$2&" "&$H$1&RIGHT(S17,2)&" Kuressaare CHP - "&'EB1'!$O$3 -> Power Plants Existing00 Kuressaare CHP - Biomass | U17: TWh | V17: GW | W17: DAYNITE
B18: =S18 -> ELCCEBIO_PAIDE00 | C18: =$B$2&RIGHT(Sector_Fuels_ELC!$L$9,3) -> ELCBIO | D18: =ELC!$X$5 -> ELC | E18: 0.0017 | G18: 0.29 | H18: 0.95 | I18: 4516.7133 | J18: 162.96753 | K18: 2.8138 | L18: 40 | M18: 8.76 | N18: 1 | Q18: ELE | S18: =$B$2&$D$5&$H$2&RIGHT(Sector_Fuels_ELC!$L$9,3)&"_PAIDE00" -> ELCCEBIO_PAIDE00 | T18: =$D$2&" "&$H$1&RIGHT(S18,2)&" Paide CHP - "&'EB1'!$O$3 -> Power Plants Existing00 Paide CHP - Biomass | U18: TWh | V18: GW | W18: DAYNITE
B19: =S19 -> ELCCEGAS_JAMEJALA00 | C19: =$B$2&RIGHT(Sector_Fuels_ELC!$L$6,3) -> ELCGAS | D19: =ELC!$X$5 -> ELC | E19: 0.0018 | G19: 0.56 | H19: 0.95 | I19: 1175.5067 | J19: 39.138496 | K19: 5.8775 | L19: 40 | M19: 8.76 | N19: 1 | Q19: ELE | S19: =$B$2&$D$5&$H$2&RIGHT(Sector_Fuels_ELC!$L$6,3)&"_JAMEJALA00" -> ELCCEGAS_JAMEJALA00 | T19: =$D$2&" "&$H$1&RIGHT(S19,2)&" Jamejala CHP - "&'EB1'!$E$3 -> Power Plants Existing00 Jamejala CHP - Natural Gas | U19: TWh | V19: GW | W19: DAYNITE
B20: =S20 -> ELCCEGAS_PUSSI00 | C20: =$B$2&RIGHT(Sector_Fuels_ELC!$L$6,3) -> ELCGAS | D20: =ELC!$X$5 -> ELC | E20: 0.0018 | G20: 0.56 | H20: 0.95 | I20: 1175.5067 | J20: 39.138496 | K20: 5.8775 | L20: 40 | M20: 8.76 | N20: 1 | Q20: ELE | S20: =$B$2&$D$5&$H$2&RIGHT(Sector_Fuels_ELC!$L$6,3)&"_PUSSI00" -> ELCCEGAS_PUSSI00 | T20: =$D$2&" "&$H$1&RIGHT(S20,2)&" Pussi CHP - "&'EB1'!$E$3 -> Power Plants Existing00 Pussi CHP - Natural Gas | U20: TWh | V20: GW | W20: DAYNITE
B21: =S21 -> ELCCEBIO_ILMATSALU00 | C21: =$B$2&RIGHT(Sector_Fuels_ELC!$L$9,3) -> ELCBIO | D21: =ELC!$X$5 -> ELC | E21: 0.0015 | G21: 0.29 | H21: 0.95 | I21: 4516.7133 | J21: 162.96753 | K21: 2.8138 | L21: 40 | M21: 8.76 | N21: 1 | Q21: ELE | S21: =$B$2&$D$5&$H$2&RIGHT(Sector_Fuels_ELC!$L$9,3)&"_ILMATSALU00" -> ELCCEBIO_ILMATSALU00 | T21: =$D$2&" "&$H$1&RIGHT(S21,2)&" Ilmatsalu CHP - "&'EB1'!$O$3 -> Power Plants Existing00 Ilmatsalu CHP - Biomass | U21: TWh | V21: GW | W21: DAYNITE
B22: =S22 -> ELCCEBIO_VINNI00 | C22: =$B$2&RIGHT(Sector_Fuels_ELC!$L$9,3) -> ELCBIO | D22: =ELC!$X$5 -> ELC | E22: 0.0014 | G22: 0.29 | H22: 0.95 | I22: 4516.7133 | J22: 162.96753 | K22: 2.8138 | L22: 40 | M22: 8.76 | N22: 1 | Q22: ELE | S22: =$B$2&$D$5&$H$2&RIGHT(Sector_Fuels_ELC!$L$9,3)&"_VINNI00" -> ELCCEBIO_VINNI00 | T22: =$D$2&" "&$H$1&RIGHT(S22,2)&" Vinni CHP - "&'EB1'!$O$3 -> Power Plants Existing00 Vinni CHP - Biomass | U22: TWh | V22: GW | W22: DAYNITE
B23: =S23 -> ELCCEBIO_OISU00 | C23: =$B$2&RIGHT(Sector_Fuels_ELC!$L$9,3) -> ELCBIO | D23: =ELC!$X$5 -> ELC | E23: 0.0012 | G23: 0.29 | H23: 0.95 | I23: 4516.7133 | J23: 162.96753 | K23: 2.8138 | L23: 40 | M23: 8.76 | N23: 1 | Q23: ELE | S23: =$B$2&$D$5&$H$2&RIGHT(Sector_Fuels_ELC!$L$9,3)&"_OISU00" -> ELCCEBIO_OISU00 | T23: =$D$2&" "&$H$1&RIGHT(S23,2)&" Oisu CHP - "&'EB1'!$O$3 -> Power Plants Existing00 Oisu CHP - Biomass | U23: TWh | V23: GW | W23: DAYNITE
B24: =S24 -> ELCCEBIO_RAKVERE00 | C24: =$B$2&RIGHT(Sector_Fuels_ELC!$L$9,3) -> ELCBIO | D24: =ELC!$X$5 -> ELC | E24: 0.0009 | G24: 0.29 | H24: 0.95 | I24: 4516.7133 | J24: 162.96753 | K24: 2.8138 | L24: 40 | M24: 8.76 | N24: 1 | Q24: ELE | S24: =$B$2&$D$5&$H$2&RIGHT(Sector_Fuels_ELC!$L$9,3)&"_RAKVERE00" -> ELCCEBIO_RAKVERE00 | T24: =$D$2&" "&$H$1&RIGHT(S24,2)&" Rakvere CHP - "&'EB1'!$O$3 -> Power Plants Existing00 Rakvere CHP - Biomass | U24: TWh | V24: GW | W24: DAYNITE

Sheet Emi
B3: Dynamic coefficients for combustion emissions in power sector
B5: ~COMEMI
B6: CommName | C6: =Sector_Fuels_ELC!$L$5 -> ELCCOA | D6: =Sector_Fuels_ELC!$L$6 -> ELCGAS | E6: =Sector_Fuels_ELC!$L$7 -> ELCOIL | F6: =Sector_Fuels_ELC!$L$16 -> ELCSHL | G6: =Sector_Fuels_ELC!$L$15 -> ELCMSW
B7: *Units | C7: kt/PJ | D7: kt/PJ | E7: kt/PJ | F7: kt/PJ | G7: kt/PJ
B8: =ELC!$X$6 -> ELCCO2 | C8: 95 | D8: 515 | E8: 76.4 | F8: 900 | G8: 41.4
D9: 56.1 | F9: 100
C23: User inputs
C24: Linked to the Energy Balance

Sheet TOTCO2
B4: ~COMAGG
B5: CommName | C5: AGRCO2 | D5: COMCO2 | E5: RSDCO2 | F5: ELCCO2 | G5: TRACO2 | H5: INDCO2
B6: TOTCO2 | C6: 1 | D6: 1 | E6: 1 | F6: 1 | G6: 1 | H6: 1
B9: ~FI_Comm
B10: Csets | C10: Region | D10: CommName | E10: CommDesc | F10: Unit | G10: LimType | H10: CTSLvl | I10: PeakTS | J10: Ctype
B11: *Commodity Set Membership | C11: Region Name | D11: Commodity Name | E11: Commodity Description | F11: Unit | G11: Sense of the Balance EQN. | H11: Timeslice Level | I11: Peak Monitoring | J11: Electricity Indicator
B12: ENV | D12: =B6 -> TOTCO2 | E12: Total CO2 | F12: =[2]EB1!AA2 -> kt
