Workbook

Sheet Veda
G1: 1,2,3,4,5,6,7,8,9,10,11,12,13,14,15,21,22,23,24,25,31,32,33,34,35,36,37,38,39,40,41,42,43,44,45,46,47,48,49,50,56,57,58,59,60,66,67,68,69,70
D2: ="~Inputcell: "&_xlfn.TEXTJOIN(",",TRUE,G1:EE1) -> ~Inputcell: 1,2,3,4,5,6,7,8,9,10,11,12,13,14,15,21,22,23,24,25,31,32,33,34,35,36,37,38,39,40,41,42,43,44,45,46,47,48,49,50,56,57,58,59,60,66,67,68,69,70 | G2: 5 | H2: 6 | I2: 7 | J2: 9 | K2: 10 | L2: 11 | M2: 16 | N2: 17 | O2: 18 | P2: 20 | Q2: 21 | R2: 22 | S2: 27 | T2: 28 | U2: 29 | V2: 31 | W2: 32 | X2: 33 | Y2: 38 | Z2: 39 | AA2: 40 | AB2: 42 | AC2: 43 | AD2: 44 | AE2: 49 | AF2: 50 | AG2: 51 | AH2: 53 | AI2: 54 | AJ2: 55
D3: 1
D5: =VLOOKUP(D3,$C$9:$E$999,2,FALSE) -> ts_annual | E5: =VLOOKUP(D3,$C$9:$E$999,3,FALSE) -> C1
B7: ~Scenmap
A8: priority | B8: scen | C8: case_no | D8: timeslice | E8: climate
A9: 5 | B9: =VLOOKUP(E9,$AK$9:$AL$15,2,FALSE)&"."&VLOOKUP(D9,$AH$9:$AI$24,2,FALSE) -> e 1.5 deg no OS.kAnn | C9: 1 | D9: =VLOOKUP(AJ9,$AG$9:$AH$22,2,FALSE) -> ts_annual | E9: C1 | G9: Limit warming to 1.5°C (>50%) with no or limited overshoot | AG9: 1 | AH9: ts_annual | AI9: kAnn | AJ9: 1 | AK9: C1 | AL9: e 1.5 deg no OS
A10: 5 | B10: =VLOOKUP(E10,$AK$9:$AL$15,2,FALSE)&"."&VLOOKUP(D10,$AH$9:$AI$24,2,FALSE) -> d 1.5 deg OS.kAnn | C10: =C9+1 -> 2 | D10: =VLOOKUP(AJ10,$AG$9:$AH$22,2,FALSE) -> ts_annual | E10: C2 | G10: Limit warming to 1.5°C (>67%) with high overshoot | S10: IEA | AG10: 2 | AH10: ts_12t | AI10: k12 | AJ10: 1 | AK10: C2 | AL10: d 1.5 deg OS
A11: 5 | B11: =VLOOKUP(E11,$AK$9:$AL$15,2,FALSE)&"."&VLOOKUP(D11,$AH$9:$AI$24,2,FALSE) -> c 2 deg (67%).kAnn | C11: =C10+1 -> 3 | D11: =VLOOKUP(AJ11,$AG$9:$AH$22,2,FALSE) -> ts_annual | E11: C3 | G11: Limit warming to 2°C (>67%) with higher action post-2030 | S11: 2022 | AG11: 3 | AH11: ts_012 | AI11: j12 | AJ11: 1 | AK11: C3 | AL11: c 2 deg (67%)
A12: 5 | B12: =VLOOKUP(E12,$AK$9:$AL$15,2,FALSE)&"."&VLOOKUP(D12,$AH$9:$AI$24,2,FALSE) -> b 2 deg (50%).kAnn | C12: =C11+1 -> 4 | D12: =VLOOKUP(AJ12,$AG$9:$AH$22,2,FALSE) -> ts_annual | E12: C4 | G12: Limit warming to 2°C (>50%) with immediate action | S12: =SUMIFS(iea_data!I3:I9999,iea_data!$B$3:$B$9999,Veda!$S$11)+T28-T29 -> 9.95 | T12: base-year generation (TWh) | AG12: 4 | AH12: ts_024 | AI12: i24 | AJ12: 1 | AK12: C4 | AL12: b 2 deg (50%)
A13: 5 | B13: =VLOOKUP(E13,$AK$9:$AL$15,2,FALSE)&"."&VLOOKUP(D13,$AH$9:$AI$24,2,FALSE) -> a 3 deg.kAnn | C13: =C12+1 -> 5 | D13: =VLOOKUP(AJ13,$AG$9:$AH$22,2,FALSE) -> ts_annual | E13: C7 | G13: Likely above 3°C warming with limited mitigation | AG13: 5 | AH13: ts_048 | AI13: h48 | AJ13: 1 | AK13: C7 | AL13: a 3 deg
A14: 5 | B14: =VLOOKUP(E14,$AK$9:$AL$15,2,FALSE)&"."&VLOOKUP(D14,$AH$9:$AI$24,2,FALSE) -> e 1.5 deg no OS.k12 | C14: =C13+1 -> 6 | D14: =VLOOKUP(AJ14,$AG$9:$AH$22,2,FALSE) -> ts_12t | E14: =E9 -> C1 | T14: =S12 -> 9.95 | U14: =$S$12*J15 -> 10.2485 | V14: =$S$12*K15 -> 11.8405 | W14: =$S$12*L15 -> 14.2285 | X14: =$S$12*M15 -> 16.4175 | Y14: =$S$12*N15 -> 18.0095 | Z14: =$S$12*O15 -> 19.2035 | AG14: 6 | AH14: ts_064 | AI14: g64 | AJ14: =AJ9+1 -> 2
A15: 5 | B15: =VLOOKUP(E15,$AK$9:$AL$15,2,FALSE)&"."&VLOOKUP(D15,$AH$9:$AI$24,2,FALSE) -> d 1.5 deg OS.k12 | C15: =C14+1 -> 7 | D15: =VLOOKUP(AJ15,$AG$9:$AH$22,2,FALSE) -> ts_12t | E15: =E10 -> C2 | G15: Electricity growth relative to 2020 | I15: =SUMIFS(ar6_r10!$F$2:$F$999,ar6_r10!$A$2:$A$999,Veda!$E$5,ar6_r10!$C$2:$C$999,Veda!I$17,ar6_r10!$M$2:$M$999,Veda!$G15) -> 1 | J15: =SUMIFS(ar6_r10!$F$2:$F$999,ar6_r10!$A$2:$A$999,Veda!$E$5,ar6_r10!$C$2:$C$999,Veda!J$17,ar6_r10!$M$2:$M$999,Veda!$G15) -> 1.03 | K15: =SUMIFS(ar6_r10!$F$2:$F$999,ar6_r10!$A$2:$A$999,Veda!$E$5,ar6_r10!$C$2:$C$999,Veda!K$17,ar6_r10!$M$2:$M$999,Veda!$G15) -> 1.19 | L15: =SUMIFS(ar6_r10!$F$2:$F$999,ar6_r10!$A$2:$A$999,Veda!$E$5,ar6_r10!$C$2:$C$999,Veda!L$17,ar6_r10!$M$2:$M$999,Veda!$G15) -> 1.43 | M15: =SUMIFS(ar6_r10!$F$2:$F$999,ar6_r10!$A$2:$A$999,Veda!$E$5,ar6_r10!$C$2:$C$999,Veda!M$17,ar6_r10!$M$2:$M$999,Veda!$G15) -> 1.65 | N15: =SUMIFS(ar6_r10!$F$2:$F$999,ar6_r10!$A$2:$A$999,Veda!$E$5,ar6_r10!$C$2:$C$999,Veda!N$17,ar6_r10!$M$2:$M$999,Veda!$G15) -> 1.81 | O15: =SUMIFS(ar6_r10!$F$2:$F$999,ar6_r10!$A$2:$A$999,Veda!$E$5,ar6_r10!$C$2:$C$999,Veda!O$17,ar6_r10!$M$2:$M$999,Veda!$G15) -> 1.93 | AG15: 7 | AH15: ts_096P50 | AI15: f96p50 | AJ15: =AJ10+1 -> 2
A16: 5 | B16: =VLOOKUP(E16,$AK$9:$AL$15,2,FALSE)&"."&VLOOKUP(D16,$AH$9:$AI$24,2,FALSE) -> c 2 deg (67%).k12 | C16: =C15+1 -> 8 | D16: =VLOOKUP(AJ16,$AG$9:$AH$22,2,FALSE) -> ts_12t | E16: =E11 -> C3 | S16: ~TFM_INS-TS | AG16: 8 | AH16: ts_096P10 | AI16: f96p10 | AJ16: =AJ11+1 -> 2
A17: 5 | B17: =VLOOKUP(E17,$AK$9:$AL$15,2,FALSE)&"."&VLOOKUP(D17,$AH$9:$AI$24,2,FALSE) -> b 2 deg (50%).k12 | C17: =C16+1 -> 9 | D17: =VLOOKUP(AJ17,$AG$9:$AH$22,2,FALSE) -> ts_12t | E17: =E12 -> C4 | I17: 2020 | J17: =U17 -> 2025 | K17: =V17 -> 2030 | L17: =W17 -> 2035 | M17: =X17 -> 2040 | N17: =Y17 -> 2045 | O17: =Z17 -> 2050 | S17: commodity | T17: 2022 | U17: 2025 | V17: 2030 | W17: 2035 | X17: 2040 | Y17: 2045 | Z17: 2050 | AA17: attribute | AG17: 9 | AH17: ts_096P90 | AI17: f96p90 | AJ17: =AJ12+1 -> 2
A18: 5 | B18: =VLOOKUP(E18,$AK$9:$AL$15,2,FALSE)&"."&VLOOKUP(D18,$AH$9:$AI$24,2,FALSE) -> a 3 deg.k12 | C18: =C17+1 -> 10 | D18: =VLOOKUP(AJ18,$AG$9:$AH$22,2,FALSE) -> ts_12t | E18: =E13 -> C7 | G18: Hydrogen as a share of electricity | I18: =SUMIFS(ar6_r10!$F$2:$F$999,ar6_r10!$A$2:$A$999,Veda!$E$5,ar6_r10!$C$2:$C$999,Veda!I$17,ar6_r10!$M$2:$M$999,Veda!$G18) -> 0.01 | J18: =SUMIFS(ar6_r10!$F$2:$F$999,ar6_r10!$A$2:$A$999,Veda!$E$5,ar6_r10!$C$2:$C$999,Veda!J$17,ar6_r10!$M$2:$M$999,Veda!$G18) -> 0.01 | K18: =SUMIFS(ar6_r10!$F$2:$F$999,ar6_r10!$A$2:$A$999,Veda!$E$5,ar6_r10!$C$2:$C$999,Veda!K$17,ar6_r10!$M$2:$M$999,Veda!$G18) -> 0.01 | L18: =SUMIFS(ar6_r10!$F$2:$F$999,ar6_r10!$A$2:$A$999,Veda!$E$5,ar6_r10!$C$2:$C$999,Veda!L$17,ar6_r10!$M$2:$M$999,Veda!$G18) -> 0.03 | M18: =SUMIFS(ar6_r10!$F$2:$F$999,ar6_r10!$A$2:$A$999,Veda!$E$5,ar6_r10!$C$2:$C$999,Veda!M$17,ar6_r10!$M$2:$M$999,Veda!$G18) -> 0.03 | N18: =SUMIFS(ar6_r10!$F$2:$F$999,ar6_r10!$A$2:$A$999,Veda!$E$5,ar6_r10!$C$2:$C$999,Veda!N$17,ar6_r10!$M$2:$M$999,Veda!$G18) -> 0.04 | O18: =SUMIFS(ar6_r10!$F$2:$F$999,ar6_r10!$A$2:$A$999,Veda!$E$5,ar6_r10!$C$2:$C$999,Veda!O$17,ar6_r10!$M$2:$M$999,Veda!$G18) -> 0.05 | S18: hydrogen_allsect | T18: =I18*T$14 -> 0.0995 | U18: =J18*U$14 -> 0.102485 | V18: =K18*V$14 -> 0.118405 | W18: =L18*W$14 -> 0.426855 | X18: =M18*X$14 -> 0.492525 | Y18: =N18*Y$14 -> 0.72038 | Z18: =O18*Z$14 -> 0.960175 | AA18: demand | AG18: 10 | AH18: s1p1v1_d | AI18: e3d | AJ18: =AJ13+1 -> 2
A19: 5 | B19: =VLOOKUP(E19,$AK$9:$AL$15,2,FALSE)&"."&VLOOKUP(D19,$AH$9:$AI$24,2,FALSE) -> e 1.5 deg no OS.j12 | C19: =C18+1 -> 11 | D19: =VLOOKUP(AJ19,$AG$9:$AH$22,2,FALSE) -> ts_012 | E19: =E14 -> C1 | G19: Industry electricity share | I19: =SUMIFS(ar6_r10!$F$2:$F$999,ar6_r10!$A$2:$A$999,Veda!$E$5,ar6_r10!$C$2:$C$999,Veda!I$17,ar6_r10!$M$2:$M$999,Veda!$G19) -> 0.35 | J19: =SUMIFS(ar6_r10!$F$2:$F$999,ar6_r10!$A$2:$A$999,Veda!$E$5,ar6_r10!$C$2:$C$999,Veda!J$17,ar6_r10!$M$2:$M$999,Veda!$G19) -> 0.32 | K19: =SUMIFS(ar6_r10!$F$2:$F$999,ar6_r10!$A$2:$A$999,Veda!$E$5,ar6_r10!$C$2:$C$999,Veda!K$17,ar6_r10!$M$2:$M$999,Veda!$G19) -> 0.3 | L19: =SUMIFS(ar6_r10!$F$2:$F$999,ar6_r10!$A$2:$A$999,Veda!$E$5,ar6_r10!$C$2:$C$999,Veda!L$17,ar6_r10!$M$2:$M$999,Veda!$G19) -> 0.29 | M19: =SUMIFS(ar6_r10!$F$2:$F$999,ar6_r10!$A$2:$A$999,Veda!$E$5,ar6_r10!$C$2:$C$999,Veda!M$17,ar6_r10!$M$2:$M$999,Veda!$G19) -> 0.29 | N19: =SUMIFS(ar6_r10!$F$2:$F$999,ar6_r10!$A$2:$A$999,Veda!$E$5,ar6_r10!$C$2:$C$999,Veda!N$17,ar6_r10!$M$2:$M$999,Veda!$G19) -> 0.3 | O19: =SUMIFS(ar6_r10!$F$2:$F$999,ar6_r10!$A$2:$A$999,Veda!$E$5,ar6_r10!$C$2:$C$999,Veda!O$17,ar6_r10!$M$2:$M$999,Veda!$G19) -> 0.31 | S19: elc_industry | T19: =I19*T$14 -> 3.4825 | U19: =J19*U$14 -> 3.27952 | V19: =K19*V$14 -> 3.55215 | W19: =L19*W$14 -> 4.126265 | X19: =M19*X$14 -> 4.761075 | Y19: =N19*Y$14 -> 5.40285 | Z19: =O19*Z$14 -> 5.953085 | AA19: demand | AG19: 11 | AH19: s3p3v3_d | AI19: d9d | AJ19: =AJ14+1 -> 3
A20: 5 | B20: =VLOOKUP(E20,$AK$9:$AL$15,2,FALSE)&"."&VLOOKUP(D20,$AH$9:$AI$24,2,FALSE) -> d 1.5 deg OS.j12 | C20: =C19+1 -> 12 | D20: =VLOOKUP(AJ20,$AG$9:$AH$22,2,FALSE) -> ts_012 | E20: =E15 -> C2 | G20: Residential and commercial electricity share | I20: =SUMIFS(ar6_r10!$F$2:$F$999,ar6_r10!$A$2:$A$999,Veda!$E$5,ar6_r10!$C$2:$C$999,Veda!I$17,ar6_r10!$M$2:$M$999,Veda!$G20) -> 0.61 | J20: =SUMIFS(ar6_r10!$F$2:$F$999,ar6_r10!$A$2:$A$999,Veda!$E$5,ar6_r10!$C$2:$C$999,Veda!J$17,ar6_r10!$M$2:$M$999,Veda!$G20) -> 0.62 | K20: =SUMIFS(ar6_r10!$F$2:$F$999,ar6_r10!$A$2:$A$999,Veda!$E$5,ar6_r10!$C$2:$C$999,Veda!K$17,ar6_r10!$M$2:$M$999,Veda!$G20) -> 0.59 | L20: =SUMIFS(ar6_r10!$F$2:$F$999,ar6_r10!$A$2:$A$999,Veda!$E$5,ar6_r10!$C$2:$C$999,Veda!L$17,ar6_r10!$M$2:$M$999,Veda!$G20) -> 0.56 | M20: =SUMIFS(ar6_r10!$F$2:$F$999,ar6_r10!$A$2:$A$999,Veda!$E$5,ar6_r10!$C$2:$C$999,Veda!M$17,ar6_r10!$M$2:$M$999,Veda!$G20) -> 0.54 | N20: =SUMIFS(ar6_r10!$F$2:$F$999,ar6_r10!$A$2:$A$999,Veda!$E$5,ar6_r10!$C$2:$C$999,Veda!N$17,ar6_r10!$M$2:$M$999,Veda!$G20) -> 0.53 | O20: =SUMIFS(ar6_r10!$F$2:$F$999,ar6_r10!$A$2:$A$999,Veda!$E$5,ar6_r10!$C$2:$C$999,Veda!O$17,ar6_r10!$M$2:$M$999,Veda!$G20) -> 0.53 | S20: elc_buildings | T20: =I20*T$14 -> 6.0695 | U20: =J20*U$14 -> 6.35407 | V20: =K20*V$14 -> 6.985895 | W20: =L20*W$14 -> 7.96796 | X20: =M20*X$14 -> 8.86545 | Y20: =N20*Y$14 -> 9.545035 | Z20: =O20*Z$14 -> 10.177855 | AA20: demand | AG20: 12 | AH20: s5p5v5_d | AI20: c15d | AJ20: =AJ15+1 -> 3
A21: 5 | B21: =VLOOKUP(E21,$AK$9:$AL$15,2,FALSE)&"."&VLOOKUP(D21,$AH$9:$AI$24,2,FALSE) -> c 2 deg (67%).j12 | C21: =C20+1 -> 13 | D21: =VLOOKUP(AJ21,$AG$9:$AH$22,2,FALSE) -> ts_012 | E21: =E16 -> C3 | G21: Transportation electricity share | I21: =SUMIFS(ar6_r10!$F$2:$F$999,ar6_r10!$A$2:$A$999,Veda!$E$5,ar6_r10!$C$2:$C$999,Veda!I$17,ar6_r10!$M$2:$M$999,Veda!$G21) -> 0.03 | J21: =SUMIFS(ar6_r10!$F$2:$F$999,ar6_r10!$A$2:$A$999,Veda!$E$5,ar6_r10!$C$2:$C$999,Veda!J$17,ar6_r10!$M$2:$M$999,Veda!$G21) -> 0.06 | K21: =SUMIFS(ar6_r10!$F$2:$F$999,ar6_r10!$A$2:$A$999,Veda!$E$5,ar6_r10!$C$2:$C$999,Veda!K$17,ar6_r10!$M$2:$M$999,Veda!$G21) -> 0.1 | L21: =SUMIFS(ar6_r10!$F$2:$F$999,ar6_r10!$A$2:$A$999,Veda!$E$5,ar6_r10!$C$2:$C$999,Veda!L$17,ar6_r10!$M$2:$M$999,Veda!$G21) -> 0.14 | M21: =SUMIFS(ar6_r10!$F$2:$F$999,ar6_r10!$A$2:$A$999,Veda!$E$5,ar6_r10!$C$2:$C$999,Veda!M$17,ar6_r10!$M$2:$M$999,Veda!$G21) -> 0.17 | N21: =SUMIFS(ar6_r10!$F$2:$F$999,ar6_r10!$A$2:$A$999,Veda!$E$5,ar6_r10!$C$2:$C$999,Veda!N$17,ar6_r10!$M$2:$M$999,Veda!$G21) -> 0.19 | O21: =SUMIFS(ar6_r10!$F$2:$F$999,ar6_r10!$A$2:$A$999,Veda!$E$5,ar6_r10!$C$2:$C$999,Veda!O$17,ar6_r10!$M$2:$M$999,Veda!$G21) -> 0.2 | S21: elc_transport | T21: =I21*T$14 -> 0.2985 | U21: =T21 -> 0.2985 | V21: =U21 -> 0.2985 | W21: =V21 -> 0.2985 | X21: =W21 -> 0.2985 | Y21: =X21 -> 0.2985 | Z21: =Y21 -> 0.2985 | AA21: demand | AC21: non-road transport demand assumed to be constant | AG21: 13 | AH21: s2_w | AI21: b2w | AJ21: =AJ16+1 -> 3
A22: 5 | B22: =VLOOKUP(E22,$AK$9:$AL$15,2,FALSE)&"."&VLOOKUP(D22,$AH$9:$AI$24,2,FALSE) -> b 2 deg (50%).j12 | C22: =C21+1 -> 14 | D22: =VLOOKUP(AJ22,$AG$9:$AH$22,2,FALSE) -> ts_012 | E22: =E17 -> C4 | S22: elc_roadtransport | T22: =T14-SUM(T19:T21) -> 0.0995 | U22: =U14-SUM(U19:U21) -> 0.31641 | V22: =V14-SUM(V19:V21) -> 1.003955 | W22: =W14-SUM(W19:W21) -> 1.835775 | X22: =X14-SUM(X19:X21) -> 2.492475 | Y22: =Y14-SUM(Y19:Y21) -> 2.763115 | Z22: =Z14-SUM(Z19:Z21) -> 2.77406 | AA22: demand | AG22: 14 | AH22: s2_w_p2_d | AI22: a2w2d | AJ22: =AJ17+1 -> 3
A23: 5 | B23: =VLOOKUP(E23,$AK$9:$AL$15,2,FALSE)&"."&VLOOKUP(D23,$AH$9:$AI$24,2,FALSE) -> a 3 deg.j12 | C23: =C22+1 -> 15 | D23: =VLOOKUP(AJ23,$AG$9:$AH$22,2,FALSE) -> ts_012 | E23: =E18 -> C7 | S23: * | AJ23: =AJ18+1 -> 3
A24: 5 | B24: =VLOOKUP(E24,$AK$9:$AL$15,2,FALSE)&"."&VLOOKUP(D24,$AH$9:$AI$24,2,FALSE) -> e 1.5 deg no OS.i24 | C24: =C23+1 -> 16 | D24: =VLOOKUP(AJ24,$AG$9:$AH$22,2,FALSE) -> ts_024 | E24: =E19 -> C1 | G24: CO2 price | I24: 0 | J24: 0 | K24: =SUMIFS(ar6_r10!$F$2:$F$999,ar6_r10!$A$2:$A$999,Veda!$E$5,ar6_r10!$C$2:$C$999,Veda!K$17,ar6_r10!$M$2:$M$999,Veda!$G24) -> 241.69 | L24: =SUMIFS(ar6_r10!$F$2:$F$999,ar6_r10!$A$2:$A$999,Veda!$E$5,ar6_r10!$C$2:$C$999,Veda!L$17,ar6_r10!$M$2:$M$999,Veda!$G24) -> 339.03 | M24: =SUMIFS(ar6_r10!$F$2:$F$999,ar6_r10!$A$2:$A$999,Veda!$E$5,ar6_r10!$C$2:$C$999,Veda!M$17,ar6_r10!$M$2:$M$999,Veda!$G24) -> 410.28 | N24: =SUMIFS(ar6_r10!$F$2:$F$999,ar6_r10!$A$2:$A$999,Veda!$E$5,ar6_r10!$C$2:$C$999,Veda!N$17,ar6_r10!$M$2:$M$999,Veda!$G24) -> 494.2 | O24: =SUMIFS(ar6_r10!$F$2:$F$999,ar6_r10!$A$2:$A$999,Veda!$E$5,ar6_r10!$C$2:$C$999,Veda!O$17,ar6_r10!$M$2:$M$999,Veda!$G24) -> 635.43 | S24: co2net | U24: 0 | V24: =K24/1000 -> 0.24169 | W24: =L24/1000 -> 0.33903 | X24: =M24/1000 -> 0.41028 | Y24: =N24/1000 -> 0.4942 | Z24: =O24/1000 -> 0.63543 | AA24: com_taxnet | AJ24: =AJ19+1 -> 4
A25: 5 | B25: =VLOOKUP(E25,$AK$9:$AL$15,2,FALSE)&"."&VLOOKUP(D25,$AH$9:$AI$24,2,FALSE) -> d 1.5 deg OS.i24 | C25: =C24+1 -> 17 | D25: =VLOOKUP(AJ25,$AG$9:$AH$22,2,FALSE) -> ts_024 | E25: =E20 -> C2 | AJ25: =AJ20+1 -> 4
A26: 5 | B26: =VLOOKUP(E26,$AK$9:$AL$15,2,FALSE)&"."&VLOOKUP(D26,$AH$9:$AI$24,2,FALSE) -> c 2 deg (67%).i24 | C26: =C25+1 -> 18 | D26: =VLOOKUP(AJ26,$AG$9:$AH$22,2,FALSE) -> ts_024 | E26: =E21 -> C3 | S26: ~TFM_INS-TS | AJ26: =AJ21+1 -> 4
A27: 5 | B27: =VLOOKUP(E27,$AK$9:$AL$15,2,FALSE)&"."&VLOOKUP(D27,$AH$9:$AI$24,2,FALSE) -> b 2 deg (50%).i24 | C27: =C26+1 -> 19 | D27: =VLOOKUP(AJ27,$AG$9:$AH$22,2,FALSE) -> ts_024 | E27: =E22 -> C4 | S27: process | T27: =T17 -> 2022 | U27: =U17 -> 2025 | V27: =V17 -> 2030 | W27: =W17 -> 2035 | X27: =X17 -> 2040 | Y27: =Y17 -> 2045 | Z27: =Z17 -> 2050 | AA27: attribute | AB27: limtype | AJ27: =AJ22+1 -> 4
A28: 5 | B28: =VLOOKUP(E28,$AK$9:$AL$15,2,FALSE)&"."&VLOOKUP(D28,$AH$9:$AI$24,2,FALSE) -> a 3 deg.i24 | C28: =C27+1 -> 20 | D28: =VLOOKUP(AJ28,$AG$9:$AH$22,2,FALSE) -> ts_024 | E28: =E23 -> C7 | Q28: =SUMIFS(iea_data!G3:G9999,iea_data!$B$3:$B$9999,Veda!$S$11) -> 7.18 | S28: Trd_electricity import | T28: =Q28 -> 7.18 | U28: =T28-T28*U32 -> 6.462 | V28: =U28-U28*V32 -> 5.8158 | W28: =V28-V28*W32 -> 5.23422 | X28: =W28-W28*X32 -> 4.187376 | Y28: =X28-X28*Y32 -> 3.3499008 | Z28: =Y28-Y28*Z32 -> 2.6799206 | AA28: ACT_BND | AB28: FX | AJ28: =AJ23+1 -> 4
A29: 5 | B29: =VLOOKUP(E29,$AK$9:$AL$15,2,FALSE)&"."&VLOOKUP(D29,$AH$9:$AI$24,2,FALSE) -> e 1.5 deg no OS.h48 | C29: =C28+1 -> 21 | D29: =VLOOKUP(AJ29,$AG$9:$AH$22,2,FALSE) -> ts_048 | E29: =E24 -> C1 | Q29: =SUMIFS(iea_data!H3:H9999,iea_data!$B$3:$B$9999,Veda!$S$11) -> -6.17 | S29: Trd_electricity export | T29: =-1*Q29 -> 6.17 | AA29: ACT_BND | AB29: FX | AJ29: =AJ24+1 -> 5
A30: 5 | B30: =VLOOKUP(E30,$AK$9:$AL$15,2,FALSE)&"."&VLOOKUP(D30,$AH$9:$AI$24,2,FALSE) -> d 1.5 deg OS.h48 | C30: =C29+1 -> 22 | D30: =VLOOKUP(AJ30,$AG$9:$AH$22,2,FALSE) -> ts_048 | E30: =E25 -> C2 | AJ30: =AJ25+1 -> 5
A31: 5 | B31: =VLOOKUP(E31,$AK$9:$AL$15,2,FALSE)&"."&VLOOKUP(D31,$AH$9:$AI$24,2,FALSE) -> c 2 deg (67%).h48 | C31: =C30+1 -> 23 | D31: =VLOOKUP(AJ31,$AG$9:$AH$22,2,FALSE) -> ts_048 | E31: =E26 -> C3 | AJ31: =AJ26+1 -> 5
A32: 5 | B32: =VLOOKUP(E32,$AK$9:$AL$15,2,FALSE)&"."&VLOOKUP(D32,$AH$9:$AI$24,2,FALSE) -> b 2 deg (50%).h48 | C32: =C31+1 -> 24 | D32: =VLOOKUP(AJ32,$AG$9:$AH$22,2,FALSE) -> ts_048 | E32: =E27 -> C4 | U32: 0.1 | V32: 0.1 | W32: 0.1 | X32: 0.2 | Y32: 0.2 | Z32: 0.2 | AJ32: =AJ27+1 -> 5
A33: 5 | B33: =VLOOKUP(E33,$AK$9:$AL$15,2,FALSE)&"."&VLOOKUP(D33,$AH$9:$AI$24,2,FALSE) -> a 3 deg.h48 | C33: =C32+1 -> 25 | D33: =VLOOKUP(AJ33,$AG$9:$AH$22,2,FALSE) -> ts_048 | E33: =E28 -> C7 | AJ33: =AJ28+1 -> 5
A34: 5 | B34: =VLOOKUP(E34,$AK$9:$AL$15,2,FALSE)&"."&VLOOKUP(D34,$AH$9:$AI$24,2,FALSE) -> e 1.5 deg no OS.g64 | C34: =C33+1 -> 26 | D34: =VLOOKUP(AJ34,$AG$9:$AH$22,2,FALSE) -> ts_064 | E34: =E29 -> C1 | AJ34: =AJ29+1 -> 6
A35: 5 | B35: =VLOOKUP(E35,$AK$9:$AL$15,2,FALSE)&"."&VLOOKUP(D35,$AH$9:$AI$24,2,FALSE) -> d 1.5 deg OS.g64 | C35: =C34+1 -> 27 | D35: =VLOOKUP(AJ35,$AG$9:$AH$22,2,FALSE) -> ts_064 | E35: =E30 -> C2 | AJ35: =AJ30+1 -> 6
A36: 5 | B36: =VLOOKUP(E36,$AK$9:$AL$15,2,FALSE)&"."&VLOOKUP(D36,$AH$9:$AI$24,2,FALSE) -> c 2 deg (67%).g64 | C36: =C35+1 -> 28 | D36: =VLOOKUP(AJ36,$AG$9:$AH$22,2,FALSE) -> ts_064 | E36: =E31 -> C3 | G36: C7 | AJ36: =AJ31+1 -> 6
A37: 5 | B37: =VLOOKUP(E37,$AK$9:$AL$15,2,FALSE)&"."&VLOOKUP(D37,$AH$9:$AI$24,2,FALSE) -> b 2 deg (50%).g64 | C37: =C36+1 -> 29 | D37: =VLOOKUP(AJ37,$AG$9:$AH$22,2,FALSE) -> ts_064 | E37: =E32 -> C4 | G37: Gas Price | I37: =SUMIFS(ar6_r10!$F$2:$F$999,ar6_r10!$A$2:$A$999,Veda!$G$36,ar6_r10!$C$2:$C$999,Veda!I$17,ar6_r10!$M$2:$M$999,Veda!$G37) -> 1 | J37: =SUMIFS(ar6_r10!$F$2:$F$999,ar6_r10!$A$2:$A$999,Veda!$G$36,ar6_r10!$C$2:$C$999,Veda!J$17,ar6_r10!$M$2:$M$999,Veda!$G37) -> 1.07 | K37: =SUMIFS(ar6_r10!$F$2:$F$999,ar6_r10!$A$2:$A$999,Veda!$G$36,ar6_r10!$C$2:$C$999,Veda!K$17,ar6_r10!$M$2:$M$999,Veda!$G37) -> 1.24 | L37: =SUMIFS(ar6_r10!$F$2:$F$999,ar6_r10!$A$2:$A$999,Veda!$G$36,ar6_r10!$C$2:$C$999,Veda!L$17,ar6_r10!$M$2:$M$999,Veda!$G37) -> 1.15 | M37: =SUMIFS(ar6_r10!$F$2:$F$999,ar6_r10!$A$2:$A$999,Veda!$G$36,ar6_r10!$C$2:$C$999,Veda!M$17,ar6_r10!$M$2:$M$999,Veda!$G37) -> 1.25 | N37: =SUMIFS(ar6_r10!$F$2:$F$999,ar6_r10!$A$2:$A$999,Veda!$G$36,ar6_r10!$C$2:$C$999,Veda!N$17,ar6_r10!$M$2:$M$999,Veda!$G37) -> 1.17 | O37: =SUMIFS(ar6_r10!$F$2:$F$999,ar6_r10!$A$2:$A$999,Veda!$G$36,ar6_r10!$C$2:$C$999,Veda!O$17,ar6_r10!$M$2:$M$999,Veda!$G37) -> 1.34 | AJ37: =AJ32+1 -> 6
A38: 5 | B38: =VLOOKUP(E38,$AK$9:$AL$15,2,FALSE)&"."&VLOOKUP(D38,$AH$9:$AI$24,2,FALSE) -> a 3 deg.g64 | C38: =C37+1 -> 30 | D38: =VLOOKUP(AJ38,$AG$9:$AH$22,2,FALSE) -> ts_064 | E38: =E33 -> C7 | G38: Coal Price | I38: =SUMIFS(ar6_r10!$F$2:$F$999,ar6_r10!$A$2:$A$999,Veda!$G$36,ar6_r10!$C$2:$C$999,Veda!I$17,ar6_r10!$M$2:$M$999,Veda!$G38) -> 1 | J38: =SUMIFS(ar6_r10!$F$2:$F$999,ar6_r10!$A$2:$A$999,Veda!$G$36,ar6_r10!$C$2:$C$999,Veda!J$17,ar6_r10!$M$2:$M$999,Veda!$G38) -> 1.02 | K38: =SUMIFS(ar6_r10!$F$2:$F$999,ar6_r10!$A$2:$A$999,Veda!$G$36,ar6_r10!$C$2:$C$999,Veda!K$17,ar6_r10!$M$2:$M$999,Veda!$G38) -> 1.06 | L38: =SUMIFS(ar6_r10!$F$2:$F$999,ar6_r10!$A$2:$A$999,Veda!$G$36,ar6_r10!$C$2:$C$999,Veda!L$17,ar6_r10!$M$2:$M$999,Veda!$G38) -> 1.07 | M38: =SUMIFS(ar6_r10!$F$2:$F$999,ar6_r10!$A$2:$A$999,Veda!$G$36,ar6_r10!$C$2:$C$999,Veda!M$17,ar6_r10!$M$2:$M$999,Veda!$G38) -> 1.08 | N38: =SUMIFS(ar6_r10!$F$2:$F$999,ar6_r10!$A$2:$A$999,Veda!$G$36,ar6_r10!$C$2:$C$999,Veda!N$17,ar6_r10!$M$2:$M$999,Veda!$G38) -> 1.1 | O38: =SUMIFS(ar6_r10!$F$2:$F$999,ar6_r10!$A$2:$A$999,Veda!$G$36,ar6_r10!$C$2:$C$999,Veda!O$17,ar6_r10!$M$2:$M$999,Veda!$G38) -> 1.12 | AJ38: =AJ33+1 -> 6
A39: 5 | B39: =VLOOKUP(E39,$AK$9:$AL$15,2,FALSE)&"."&VLOOKUP(D39,$AH$9:$AI$24,2,FALSE) -> e 1.5 deg no OS.f96p50 | C39: =C38+1 -> 31 | D39: =VLOOKUP(AJ39,$AG$9:$AH$22,2,FALSE) -> ts_096P50 | E39: =E34 -> C1 | G39: Oil Price | I39: =SUMIFS(ar6_r10!$F$2:$F$999,ar6_r10!$A$2:$A$999,Veda!$G$36,ar6_r10!$C$2:$C$999,Veda!I$17,ar6_r10!$M$2:$M$999,Veda!$G39) -> 1 | J39: =SUMIFS(ar6_r10!$F$2:$F$999,ar6_r10!$A$2:$A$999,Veda!$G$36,ar6_r10!$C$2:$C$999,Veda!J$17,ar6_r10!$M$2:$M$999,Veda!$G39) -> 1.01 | K39: =SUMIFS(ar6_r10!$F$2:$F$999,ar6_r10!$A$2:$A$999,Veda!$G$36,ar6_r10!$C$2:$C$999,Veda!K$17,ar6_r10!$M$2:$M$999,Veda!$G39) -> 1.11 | L39: =SUMIFS(ar6_r10!$F$2:$F$999,ar6_r10!$A$2:$A$999,Veda!$G$36,ar6_r10!$C$2:$C$999,Veda!L$17,ar6_r10!$M$2:$M$999,Veda!$G39) -> 1.01 | M39: =SUMIFS(ar6_r10!$F$2:$F$999,ar6_r10!$A$2:$A$999,Veda!$G$36,ar6_r10!$C$2:$C$999,Veda!M$17,ar6_r10!$M$2:$M$999,Veda!$G39) -> 1.01 | N39: =SUMIFS(ar6_r10!$F$2:$F$999,ar6_r10!$A$2:$A$999,Veda!$G$36,ar6_r10!$C$2:$C$999,Veda!N$17,ar6_r10!$M$2:$M$999,Veda!$G39) -> 1.04 | O39: =SUMIFS(ar6_r10!$F$2:$F$999,ar6_r10!$A$2:$A$999,Veda!$G$36,ar6_r10!$C$2:$C$999,Veda!O$17,ar6_r10!$M$2:$M$999,Veda!$G39) -> 1.14 | AJ39: =AJ34+1 -> 7
A40: 5 | B40: =VLOOKUP(E40,$AK$9:$AL$15,2,FALSE)&"."&VLOOKUP(D40,$AH$9:$AI$24,2,FALSE) -> d 1.5 deg OS.f96p50 | C40: =C39+1 -> 32 | D40: =VLOOKUP(AJ40,$AG$9:$AH$22,2,FALSE) -> ts_096P50 | E40: =E35 -> C2 | G40: Biomass Price | I40: =SUMIFS(ar6_r10!$F$2:$F$999,ar6_r10!$A$2:$A$999,Veda!$G$36,ar6_r10!$C$2:$C$999,Veda!I$17,ar6_r10!$M$2:$M$999,Veda!$G40) -> 1 | J40: =SUMIFS(ar6_r10!$F$2:$F$999,ar6_r10!$A$2:$A$999,Veda!$G$36,ar6_r10!$C$2:$C$999,Veda!J$17,ar6_r10!$M$2:$M$999,Veda!$G40) -> 0.96 | K40: =SUMIFS(ar6_r10!$F$2:$F$999,ar6_r10!$A$2:$A$999,Veda!$G$36,ar6_r10!$C$2:$C$999,Veda!K$17,ar6_r10!$M$2:$M$999,Veda!$G40) -> 1.04 | L40: =SUMIFS(ar6_r10!$F$2:$F$999,ar6_r10!$A$2:$A$999,Veda!$G$36,ar6_r10!$C$2:$C$999,Veda!L$17,ar6_r10!$M$2:$M$999,Veda!$G40) -> 1.04 | M40: =SUMIFS(ar6_r10!$F$2:$F$999,ar6_r10!$A$2:$A$999,Veda!$G$36,ar6_r10!$C$2:$C$999,Veda!M$17,ar6_r10!$M$2:$M$999,Veda!$G40) -> 0.98 | N40: =SUMIFS(ar6_r10!$F$2:$F$999,ar6_r10!$A$2:$A$999,Veda!$G$36,ar6_r10!$C$2:$C$999,Veda!N$17,ar6_r10!$M$2:$M$999,Veda!$G40) -> 0.99 | O40: =SUMIFS(ar6_r10!$F$2:$F$999,ar6_r10!$A$2:$A$999,Veda!$G$36,ar6_r10!$C$2:$C$999,Veda!O$17,ar6_r10!$M$2:$M$999,Veda!$G40) -> 1 | AJ40: =AJ35+1 -> 7
A41: 5 | B41: =VLOOKUP(E41,$AK$9:$AL$15,2,FALSE)&"."&VLOOKUP(D41,$AH$9:$AI$24,2,FALSE) -> c 2 deg (67%).f96p50 | C41: =C40+1 -> 33 | D41: =VLOOKUP(AJ41,$AG$9:$AH$22,2,FALSE) -> ts_096P50 | E41: =E36 -> C3 | AJ41: =AJ36+1 -> 7
A42: 5 | B42: =VLOOKUP(E42,$AK$9:$AL$15,2,FALSE)&"."&VLOOKUP(D42,$AH$9:$AI$24,2,FALSE) -> b 2 deg (50%).f96p50 | C42: =C41+1 -> 34 | D42: =VLOOKUP(AJ42,$AG$9:$AH$22,2,FALSE) -> ts_096P50 | E42: =E37 -> C4 | AJ42: =AJ37+1 -> 7
...

Sheet fuel_prices
A9: Fuel Prices
A10: iso | B10: gas_low | C10: gas_high | D10: coal_low | E10: coal_high | F10: oil_low | G10: oil_high | H10: bioenergy_low | I10: bioenergy_high | J10: Notes
A11: EST | B11: 27.4 | C11: 39.4 | D11: 12.2 | E11: 15.2 | F11: 48 | G11: 58 | H11: 20 | I11: 28 | J11: Baltic market, forest resources

Sheet iea_data
A9: IEA Baseline Data
A10: iso | B10: year | C10: industry_twh | D10: buildings_agri_twh | E10: nonroad_transport_twh | F10: road_transport_twh | G10: imports_twh | H10: exports_twh | I10: total_production_twh
A11: EST | B11: 2000 | C11: 4.21 | D11: 3.09 | E11: 0.02 | F11: 0 | G11: 0.37 | H11: -1.3 | I11: 8.51
A12: EST | B12: 2001 | C12: 4.28 | D12: 3.27 | E12: 0.02 | F12: 0 | G12: 0.5 | H12: -1.12 | I12: 8.48
A13: EST | B13: 2002 | C13: 4.23 | D13: 3.35 | E13: 0.02 | F13: 0 | G13: 0.41 | H13: -1.1 | I13: 8.53
A14: EST | B14: 2003 | C14: 4.51 | D14: 3.47 | E14: 0.02 | F14: 0 | G14: 0.09 | H14: -1.99 | I14: 10.16
A15: EST | B15: 2004 | C15: 4.56 | D15: 3.68 | E15: 0.01 | F15: 0 | G15: 0.35 | H15: -2.14 | I15: 10.3
A16: EST | B16: 2005 | C16: 4.57 | D16: 3.76 | E16: 0.01 | F16: 0 | G16: 0.35 | H16: -1.95 | I16: 10.21
A17: EST | B17: 2006 | C17: 4.6 | D17: 4.06 | E17: 0.01 | F17: 0 | G17: 0.25 | H17: -1 | I17: 9.73
A18: EST | B18: 2007 | C18: 5.18 | D18: 4.32 | E18: 0.01 | F18: 0 | G18: 0.35 | H18: -2.76 | I18: 12.19
A19: EST | B19: 2008 | C19: 4.77 | D19: 4.59 | E19: 0.01 | F19: 0 | G19: 1.37 | H19: -2.31 | I19: 10.58
A20: EST | B20: 2009 | C20: 3.93 | D20: 4.62 | E20: 0.01 | F20: 0.02 | G20: 3.03 | H20: -2.94 | I20: 8.78
A21: EST | B21: 2010 | C21: 4.6 | D21: 4.72 | E21: 0.01 | F21: 0.02 | G21: 1.1 | H21: -4.35 | I21: 12.96
A22: EST | B22: 2011 | C22: 4.45 | D22: 4.49 | E22: 0.01 | F22: 0.02 | G22: 1.69 | H22: -5.25 | I22: 12.89
... A33: EST | B33: 2022 | C33: 4.78 | D33: 5.02 | E33: 0.01 | F33: 0.02 | G33: 7.18 | H33: -6.17 | I33: 8.94

Sheet ar6_r10
A9: AR6 Scenario Drivers
A10: Category | B10: Region | C10: Year | D10: count | E10: mean | F10: median | G10: std | H10: min | I10: max | J10: q25 | K10: q75 | L10: category_description | M10: attribute
A11: C1 | B11: R10EUROPE | C11: 2020 | D11: 60 | E11: 8.68 | F11: 6.87 | G11: 10.43 | H11: 0 | I11: 55.17 | J11: 0 | K11: 13.64 | L11: Limit warming to 1.5°C (>50%) with no or limited overshoot | M11: CO2 price
A12: C1 | B12: R10EUROPE | C12: 2025 | D12: 60 | E12: 190.52 | F12: 181.51 | G12: 136.23 | H12: 1.81 | I12: 626.48 | J12: 115.48 | K12: 238.58 | L12: Limit warming to 1.5°C (>50%) with no or limited overshoot | M12: CO2 price
A13: C1 | B13: R10EUROPE | C13: 2030 | D13: 60 | E13: 268.18 | F13: 241.69 | G13: 134.29 | H13: 1.27 | I13: 673.46 | J13: 182.47 | K13: 329.7 | L13: Limit warming to 1.5°C (>50%) with no or limited overshoot | M13: CO2 price
A14: C1 | B14: R10EUROPE | C14: 2035 | D14: 60 | E14: 363.27 | F14: 339.03 | G14: 173.79 | H14: 14.37 | I14: 859.53 | J14: 227.05 | K14: 483.38 | L14: Limit warming to 1.5°C (>50%) with no or limited overshoot | M14: CO2 price
A15: C1 | B15: R10EUROPE | C15: 2040 | D15: 60 | E15: 471.65 | F15: 410.28 | G15: 224.31 | H15: 162.1 | I15: 1097.01 | J15: 298.63 | K15: 622.14 | L15: Limit warming to 1.5°C (>50%) with no or limited overshoot | M15: CO2 price
A16: C1 | B16: R10EUROPE | C16: 2045 | D16: 60 | E16: 565.69 | F16: 494.2 | G16: 256.15 | H16: 193.42 | I16: 1269.88 | J16: 352.78 | K16: 748.01 | L16: Limit warming to 1.5°C (>50%) with no or limited overshoot | M16: CO2 price
A17: C1 | B17: R10EUROPE | C17: 2050 | D17: 60 | E17: 647.44 | F17: 635.43 | G17: 273.56 | H17: 209.76 | I17: 1170.26 | J17: 409.79 | K17: 887.68 | L17: Limit warming to 1.5°C (>50%) with no or limited overshoot | M17: CO2 price
A18: C2 | B18: R10EUROPE | C18: 2020 | D18: 86 | E18: 6.44 | F18: 0 | G18: 8.34 | H18: 0 | I18: 24.5 | J18: 0 | K18: 12.68 | L18: Limit warming to 1.5°C (>67%) with high overshoot | M18: CO2 price
A19: C2 | B19: R10EUROPE | C19: 2025 | D19: 75 | E19: 63.21 | F19: 44.89 | G19: 56.62 | H19: 3.21 | I19: 273 | J19: 27.09 | K19: 77.31 | L19: Limit warming to 1.5°C (>67%) with high overshoot | M19: CO2 price
A20: C2 | B20: R10EUROPE | C20: 2030 | D20: 86 | E20: 85.48 | F20: 63.36 | G20: 73.46 | H20: 0 | I20: 409.5 | J20: 50 | K20: 111.1 | L20: Limit warming to 1.5°C (>67%) with high overshoot | M20: CO2 price
A21: C2 | B21: R10EUROPE | C21: 2035 | D21: 75 | E21: 208.71 | F21: 154.82 | G21: 291.78 | H21: 60.83 | I21: 2037.12 | J21: 93.79 | K21: 206.26 | L21: Limit warming to 1.5°C (>67%) with high overshoot | M21: CO2 price
A22: C2 | B22: R10EUROPE | C22: 2040 | D22: 86 | E22: 253.33 | F22: 172.09 | G22: 359.35 | H22: 0 | I22: 2600 | J22: 119.07 | K22: 259.4 | L22: Limit warming to 1.5°C (>67%) with high overshoot | M22: CO2 price
... A221: C1 | B221: R10EUROPE | C221: 2020 | D221: 33 | E221: 1 | F221: 1 | G221: 0 | H221: 1 | I221: 1 | J221: 1 | K221: 1 | L221: Limit warming to 1.5°C (>50%) with no or limited overshoot | M221: Gas price
A222: C1 | B222: R10EUROPE | C222: 2025 | D222: 34 | E222: 65535 | F222: 2.42 | H222: 1.18 | I222: 65535 | J222: 2.01 | K222: 2.75 | L222: Limit warming to 1.5°C (>50%) with no or limited overshoot | M222: Gas price
A223: C1 | B223: R10EUROPE | C223: 2030 | D223: 34 | E223: 65535 | F223: 3.1 | H223: 1.71 | I223: 65535 | J223: 2.38 | K223: 3.46 | L223: Limit warming to 1.5°C (>50%) with no or limited overshoot | M223: Gas price
A224: C1 | B224: R10EUROPE | C224: 2035 | D224: 34 | E224: 65535 | F224: 3.54 | H224: 1.91 | I224: 65535 | J224: 2.66 | K224: 4.16 | L224: Limit warming to 1.5°C (>50%) with no or limited overshoot | M224: Gas price
A225: C1 | B225: R10EUROPE | C225: 2040 | D225: 34 | E225: 65535 | F225: 4.1 | H225: 2.27 | I225: 65535 | J225: 2.96 | K225: 4.52 | L225: Limit warming to 1.5°C (>50%) with no or limited overshoot | M225: Gas price
A226: C1 | B226: R10EUROPE | C226: 2045 | D226: 34 | E226: 65535 | F226: 3.86 | H226: 2.54 | I226: 65535 | J226: 3.3 | K226: 4.89 | L226: Limit warming to 1.5°C (>50%) with no or limited overshoot | M226: Gas price
A227: C1 | B227: R10EUROPE | C227: 2050 | D227: 34 | E227: 65535 | F227: 3.59 | H227: 2.73 | I227: 65535 | J227: 3.07 | K227: 4.06 | L227: Limit warming to 1.5°C (>50%) with no or limited overshoot | M227: Gas price
A228: C2 | B228: R10EUROPE | C228: 2020 | D228: 43 | E228: 1 | F228: 1 | G228: 0 | H228: 1 | I228: 1 | J228: 1 | K228: 1 | L228: Limit warming to 1.5°C (>67%) with high overshoot | M228: Gas price
A229: C2 | B229: R10EUROPE | C229: 2025 | D229: 44 | E229: 65535 | F229: 1.22 | H229: 0 | I229: 65535 | J229: 1.13 | K229: 1.35 | L229: Limit warming to 1.5°C (>67%) with high overshoot | M229: Gas price
A230: C2 | B230: R10EUROPE | C230: 2030 | D230: 44 | E230: 65535 | F230: 1.5 | H230: 0 | I230: 65535 | J230: 1.31 | K230: 1.83 | L230: Limit warming to 1.5°C (>67%) with high overshoot | M230: Gas price
A231: C2 | B231: R10EUROPE | C231: 2035 | D231: 44 | E231: 65535 | F231: 2.12 | H231: 0 | I231: 65535 | J231: 1.68 | K231: 2.46 | L231: Limit warming to 1.5°C (>67%) with high overshoot | M231: Gas price
A232: C2 | B232: R10EUROPE | C232: 2040 | D232: 44 | E232: 65535 | F232: 2.5 | H232: 0 | I232: 65535 | J232: 2 | K232: 2.94 | L232: Limit warming to 1.5°C (>67%) with high overshoot | M232: Gas price
A233: C2 | B233: R10EUROPE | C233: 2045 | D233: 44 | E233: 65535 | F233: 2.79 | H233: 0 | I233: 65535 | J233: 2.08 | K233: 3.44 | L233: Limit warming to 1.5°C (>67%) with high overshoot | M233: Gas price
A234: C2 | B234: R10EUROPE | C234: 2050 | D234: 44 | E234: 65535 | F234: 2.95 | H234: 0 | I234: 65535 | J234: 2.49 | K234: 3.78 | L234: Limit warming to 1.5°C (>67%) with high overshoot | M234: Gas price
A235: C3 | B235: R10EUROPE | C235: 2020 | D235: 103 | E235: 1 | F235: 1 | G235: 0 | H235: 1 | I235: 1 | J235: 1 | K235: 1 | L235: Limit warming to 2°C (>67%) with higher action post-2030 | M235: Gas price
A236: C3 | B236: R10EUROPE | C236: 2025 | D236: 112 | E236: 65535 | F236: 1.41 | H236: 0.98 | I236: 65535 | J236: 1.23 | K236: 1.96 | L236: Limit warming to 2°C (>67%) with higher action post-2030 | M236: Gas price
A237: C3 | B237: R10EUROPE | C237: 2030 | D237: 112 | E237: 65535 | F237: 2.04 | H237: 1.05 | I237: 65535 | J237: 1.52 | K237: 2.55 | L237: Limit warming to 2°C (>67%) with higher action post-2030 | M237: Gas price
A238: C3 | B238: R10EUROPE | C238: 2035 | D238: 112 | E238: 65535 | F238: 2.4 | H238: 1.05 | I238: 65535 | J238: 1.71 | K238: 3.14 | L238: Limit warming to 2°C (>67%) with higher action post-2030 | M238: Gas price
A239: C3 | B239: R10EUROPE | C239: 2040 | D239: 112 | E239: 65535 | F239: 2.6 | H239: 1.06 | I239: 65535 | J239: 1.85 | K239: 3.74 | L239: Limit warming to 2°C (>67%) with higher action post-2030 | M239: Gas price
A240: C3 | B240: R10EUROPE | C240: 2045 | D240: 112 | E240: 65535 | F240: 2.85 | H240: 1.08 | I240: 65535 | J240: 2 | K240: 4.28 | L240: Limit warming to 2°C (>67%) with higher action post-2030 | M240: Gas price
A241: C3 | B241: R10EUROPE | C241: 2050 | D241: 112 | E241: 65535 | F241: 2.97 | H241: 0 | I241: 65535 | J241: 2.15 | K241: 4.51 | L241: Limit warming to 2°C (>67%) with higher action post-2030 | M241: Gas price
A242: C4 | B242: R10EUROPE | C242: 2020 | D242: 27 | E242: 1 | F242: 1 | G242: 0 | H242: 1 | I242: 1 | J242: 1 | K242: 1 | L242: Limit warming to 2°C (>50%) with immediate action | M242: Gas price
A243: C4 | B243: R10EUROPE | C243: 2025 | D243: 27 | E243: 1.33 | F243: 1.31 | G243: 0.18 | H243: 1.06 | I243: 1.66 | J243: 1.22 | K243: 1.45 | L243: Limit warming to 2°C (>50%) with immediate action | M243: Gas price
A244: C4 | B244: R10EUROPE | C244: 2030 | D244: 27 | E244: 1.84 | F244: 2.02 | G244: 0.28 | H244: 1.24 | I244: 2.17 | J244: 1.52 | K244: 2.07 | L244: Limit warming to 2°C (>50%) with immediate action | M244: Gas price
A245: C4 | B245: R10EUROPE | C245: 2035 | D245: 27 | E245: 1.84 | F245: 1.96 | G245: 0.41 | H245: 1.19 | I245: 2.46 | J245: 1.42 | K245: 2.11 | L245: Limit warming to 2°C (>50%) with immediate action | M245: Gas price
A246: C4 | B246: R10EUROPE | C246: 2040 | D246: 27 | E246: 2.12 | F246: 2.22 | G246: 0.47 | H246: 1.41 | I246: 2.78 | J246: 1.54 | K246: 2.43 | L246: Limit warming to 2°C (>50%) with immediate action | M246: Gas price
...

Sheet ev_charging_uc
A10: =IFERROR(Veda!D5,"ts_12t") -> ts_annual | C10: day_night | D10: s1p1v1_d | F10: day_night | G10: s5p5v5_d | I10: day_night | J10: s2_w_p2_d | L10: day_night | M10: ts_012 | O10: day_night | P10: ts_048 | R10: day_night | S10: ts_096P50 | U10: day_night | V10: ts_096P10 | X10: day_night | Y10: ts_096P90 | AA10: day_night | AB10: ts_annual | AD10: day_night | AE10: ts_12t
C11: D | D11: S02aH03,S02b0216h16,S07aH03,S11c1130h17,S02b0216h07,S02b0216h10,S03aH03,S09aH05,S11c1130h13,S12d1223h07,S01aH03,S02b0216h17,S05aH03,S11c1130h11,S02b0216h18,S09aH03,S11aH03,S11aH04,S12d1223h18,S01aH04,S12d1223h09,S12d1223h17,S01aH05,S06aH05,S11c1130h08,S11c1130h10,S12aH04,S12aH05,S02b0216h12,S11c1130h09,S11c1130h16,S12d1223h14,S12d1223h15,S05aH04,S06aH03,S10aH04,S12d1223h08,S04aH03,S07aH04,S08aH03,S09aH04,S12d1223h11,S12d1223h16,S02b0216h09,S04aH04,S12d1223h10,S12d1223h12,S12d1223h13,S02b0216h13,S07aH05,S11c1130h12,S02b0216h08,S02b0216h11,S02b0216h15,S11c1130h15,S11c1130h18,S02b0216h14,S04aH05,S11c1130h07,S02aH04,S02aH05,S10aH03,S10aH05,S11c1130h14,S03aH04,S08aH05,S11aH05,S12aH03,S03aH05,S05aH05,S06aH04,S08aH04 | F11: D | G11: S01b0107h07,S01c0130h07,S01c0130h13,S02d0204h18,S02e0215h08,S02f0216h10,S04aH03,S05g0526h08,S05g0526h11,S07aH04,S08aH03,S08h0819h13,S08h0819h15,S09aH04,S10j1002h09,S10j1002h12,S11k1103h08,S11k1103h11,S11l1130h15,S11l1130h18,S12n1223h12,S12o1225h07,S01b0107h18,S01c0130h17,S01c0130h18,S02d0204h11,S02d0204h12,S02e0215h09,S02f0216h12,S02f0216h14,S04aH04,S05g0526h07,S08i0820h10,S10j1002h14,S11k1103h13,S11l1130h10,S02d0204h15,S03aH05,S05aH05,S06aH04,S08aH04,S08i0820h08,S10j1002h13,S11k1103h07,S11k1103h12,S11l1130h14,S12o1225h14,S12o1225h16,S12p1228h09,S01b0107h10,S01b0107h16,S02e0215h07,S02e0215h11,S02e0215h15,S03aH04,S05g0526h09,S08aH05,S08h0819h08,S08i0820h17,S10j1002h17,S11aH05,S11k1103h10,S11l1130h09,S11l1130h17,S12aH03,S01b0107h15,S02e0215h10,S05g0526h18,S08i0820h07,S11k1103h16,S12m1222h10,S12o1225h15,S12o1225h18,S12p1228h16,S01b0107h13,S02e0215h12,S02f0216h09,S02f0216h16,S04aH05,S11l1130h08,S12m1222h12,S12o1225h08,S12o1225h17,S12p1228h18,S01b0107h17,S02d0204h07,S02f0216h15,S05aH04,S06aH03,S08h0819h12,S08i0820h11,S10aH04,S10j1002h10,S11k1103h18,S12m1222h18,S12n1223h16,S12o1225h11,S01b0107h14,S01c0130h11,S02aH03,S02d0204h08,S02f0216h18,S05g0526h16,S07aH03,S08i0820h12,S08i0820h16,S11k1103h14,S12n1223h13,S12n1223h15,S01b0107h08,S02aH04,S02aH05,S02e0215h16,S08h0819h09,S08h0819h17,S08i0820h09,S10aH03,S10aH05,S10j1002h16,S11l1130h07,S12m1222h14,S12p1228h07,S01aH03,S02e0215h13,S02f0216h07,S02f0216h17,S05aH03,S08h0819h16,S11k1103h09,S11k1103h15,S12m1222h15,S12n1223h18,S12o1225h10,S01c0130h10,S07aH05,S08h0819h10,S10j1002h08,S11l1130h13,S12n1223h09,S12n1223h10,S12n1223h11,S12n1223h14,S12o1225h12,S01c0130h12,S01c0130h14,S02d0204h13,S08h0819h07,S08i0820h15,S09aH03,S11aH03,S11aH04,S11k1103h17,S12m1222h07,S12m1222h11,S12m1222h16,S12n1223h17,S12p1228h11,S12p1228h13,S12p1228h15,S01aH04,S01b0107h11,S01c0130h16,S02f0216h13,S08h0819h14,S08i0820h14,S11l1130h12,S11l1130h16,S12m1222h13,S02d0204h14,S02f0216h08,S02f0216h11,S05g0526h12,S05g0526h17,S08h0819h11,S12m1222h09,S12n1223h07,S12n1223h08,S12o1225h09,S12o1225h13,S12p1228h10,S12p1228h12,S12p1228h14,S01aH05,S01b0107h12,S01c0130h08,S01c0130h09,S01c0130h15,S02e0215h14,S02e0215h17,S02e0215h18,S05g0526h10,S05g0526h14,S05g0526h15,S06aH05,S08i0820h18,S10j1002h11,S10j1002h15,S10j1002h18,S11l1130h11,S12aH04,S12aH05,S12m1222h08,S12m1222h17,S12p1228h17,S01b0107h09,S02d0204h09,S02d0204h10,S02d0204h16,S02d0204h17,S03aH03,S05g0526h13,S08h0819h18,S08i0820h13,S09aH05,S10j1002h07,S12p1228h08 | I11: D | J11: S01aH04,S06b0604h07,S06b0604h17,S06b0606h12,S06b0607h12,S06b0607h18,S06b0608h17,S06b0609h10,S06b0609h11,S08c0821h17,S08c0822h09,S08c0824h08,S08c0824h12,S08c0825h14,S12d1223h09,S12d1223h17,S12e1225h15,S06b0604h14,S06b0605h07,S06b0605h09,S06b0605h14,S06b0606h13,S06b0607h11,S06b0609h08,S06b0609h14,S07aH05,S08c0823h17,S08c0825h11,S08c0826h17,S06b0606h18,S06b0607h07,S06b0607h15,S06b0608h13,S06b0610h18,S08c0822h12,S08c0823h08,S08c0823h12,S08c0826h09,S12d1223h14,S12d1223h15,S12e1225h08,S12e1225h09,S12e1225h16,S04aH03,S06b0604h11,S06b0605h08,S06b0607h14,S06b0608h14,S06b0608h15,S07aH04,S08aH03,S08c0821h08,S08c0821h09,S08c0822h14,S08c0822h17,S08c0822h18,S08c0823h14,S09aH04,S12d1223h11,S12d1223h16,S01aH05,S06aH05,S06b0604h09,S06b0604h16,S06b0605h11,S06b0607h17,S06b0609h16,S06b0610h15,S08c0820h13,S08c0820h18,S08c0821h15,S08c0824h09,S08c0824h10,S08c0824h13,S08c0825h07,S08c0825h17,S08c0826h10,S12aH04,S12aH05,S03aH03,S06b0605h18,S06b0610h08,S08c0820h07,S08c0820h16,S08c0821h16,S09aH05,S12d1223h07,S12e1225h10,S04aH05,S06b0605h15,S06b0605h16,S06b0605h17,S06b0607h10,S06b0608h07,S06b0608h09,S06b0610h09,S08c0822h16,S08c0823h11,S08c0825h10,S08c0826h14,S08c0826h16,S08c0826h18,S02aH03,S06b0606h10,S06b0606h14,S06b0606h15,S06b0606h17,S06b0607h16,S06b0608h08,S06b0609h13,S07aH03,S08c0820h11,S08c0820h12,S08c0821h10,S08c0822h08,S08c0826h11,S12e1225h11,S02aH04,S02aH05,S06b0606h07,S06b0606h09,S06b0606h11,S06b0607h09,S06b0608h18,S06b0609h12,S08c0820h10,S08c0823h10,S08c0825h09,S10aH03,S10aH05,S01aH03,S05aH03,S06b0604h13,S06b0605h13,S06b0610h07,S06b0610h14,S06b0610h17,S08c0823h18,S08c0826h08,S08c0826h15,S04aH04,S06b0609h09,S06b0610h10,S06b0610h12,S08c0820h17,S08c0821h12,S08c0822h15,S08c0824h14,S12d1223h10,S12d1223h12,S12d1223h13,S12e1225h13,S06b0604h15,S06b0606h08,S06b0606h16,S06b0608h10,S06b0609h15,S06b0609h17,S08c0820h09,S08c0821h18,S08c0825h13,S08c0825h16,S08c0826h07,S09aH03,S11aH03,S11aH04,S12d1223h18,S03aH04,S06b0604h10,S06b0607h08,S06b0608h11,S06b0609h07,S08aH05,S08c0822h13,S08c0823h07,S08c0823h15,S08c0824h07,S08c0824h15,S08c0825h15,S11aH05,S12aH03,S12e1225h07,S12e1225h14,S05aH04,S06aH03,S06b0607h13,S08c0820h15,S08c0822h11,S08c0823h16,S08c0824h11,S08c0824h16,S08c0826h12,S10aH04,S12d1223h08,S12e1225h17,S12e1225h18,S06b0605h10,S06b0605h12,S06b0608h12,S06b0608h16,S08c0821h11,S08c0821h13,S08c0822h10,S08c0823h09,S08c0824h18,S08c0825h08,S08c0825h12,S08c0825h18,S03aH05,S05aH05,S06aH04,S06b0604h08,S06b0604h12,S06b0604h18,S06b0609h18,S06b0610h11,S06b0610h13,S06b0610h16,S08aH04,S08c0820h08,S08c0820h14,S08c0821h07,S08c0821h14,S08c0822h07,S08c0823h13,S08c0824h17,S08c0826h13,S12e1225h12 | L11: D | M11: S01aH01,S03aH01,S02aH01 | O11: D | P11: S02aH04,S06aH04,S01aH03,S05aH03,S04aH04,S01aH04,S04aH03,S07aH04,S03aH03,S03aH04,S05aH04,S06aH03,S02aH03,S07aH03 | R11: D | S11: S01aH04,S09aH03,S11aH03,S11aH04,S03aH05,S05aH05,S06aH04,S08aH04,S02aH03,S07aH03,S03aH03,S09aH05,S03aH04,S08aH05,S11aH05,S12aH03,S05aH04,S06aH03,S10aH04,S01aH03,S05aH03,S01aH05,S06aH05,S12aH04,S12aH05,S04aH05,S02aH04,S02aH05,S10aH03,S10aH05,S07aH05,S04aH03,S07aH04,S08aH03,S09aH04,S04aH04 | U11: D | V11: S04aH03,S07aH04,S08aH03,S09aH04,S02aH04,S02aH05,S10aH03,S10aH05,S04aH05,S07aH05,S09aH03,S11aH03,S11aH04,S04aH04,S01aH03,S05aH03,S02aH03,S07aH03,S05aH04,S06aH03,S10aH04,S03aH03,S09aH05,S01aH04,S03aH05,S05aH05,S06aH04,S08aH04,S03aH04,S08aH05,S11aH05,S12aH03,S01aH05,S06aH05,S12aH04,S12aH05 | X11: D | Y11: S02aH04,S02aH05,S10aH03,S10aH05,S02aH03,S07aH03,S04aH03,S07aH04,S08aH03,S09aH04,S04aH04,S03aH05,S05aH05,S06aH04,S08aH04,S09aH03,S11aH03,S11aH04,S01aH05,S06aH05,S12aH04,S12aH05,S03aH03,S09aH05,S03aH04,S08aH05,S11aH05,S12aH03,S07aH05,S01aH04,S05aH04,S06aH03,S10aH04,S01aH03,S05aH03,S04aH05 | AA11: D | AB11: AllSaAllH | AD11: D | AE11: SaD,FaD,FaP,SaP,RaD,RaP,WaD,WaP
C12: N | D12: S01aH01,S02b0216h03,S04aH01,S04aH06,S06aH02,S09aH08,S11aH01,S12aH06,S02aH02,S06aH06,S11aH08,S12d1223h06,S12d1223h20,S12d1223h23,S02b0216h02,S02b0216h05,S09aH01,S11aH07,S11c1130h05,S11c1130h06,S12aH02,S12d1223h19,S03aH02,S11c1130h24,S12d1223h04,S02b0216h24,S08aH01,S09aH07,S10aH01,S11c1130h02,S01aH02,S04aH08,S06aH01,S12aH08,S01aH06,S02b0216h04,S02b0216h21,S05aH07,S07aH01,S08aH06,S10aH07,S11c1130h20,S12d1223h01,S12d1223h05,S02aH01,S05aH02,S05aH06,S11c1130h21,S01aH08,S02aH08,S02b0216h20,S03aH06,S03aH07,S10aH02,S10aH06,S11aH06,S12d1223h21,S12d1223h24,S02b0216h01,S04aH02,S08aH07,S09aH02,S11c1130h19,S03aH01,S11c1130h03,S11c1130h04,S12aH07,S02b0216h19,S05aH08,S08aH02,S09aH06,S10aH08,S12d1223h02,S02aH06,S02b0216h22,S03aH08,S04aH07,S06aH08,S11aH02,S12aH01,S12d1223h03,S01aH07,S02aH07,S02b0216h06,S05aH01,S07aH02,S07aH06,S11c1130h01,S11c1130h23,S02b0216h23,S06aH07,S07aH07,S07aH08,S08aH08,S11c1130h22,S12d1223h22 | F12: N | G12: S01c0130h22,S02aH01,S02e0215h04,S02f0216h01,S05aH02,S05aH06,S08i0820h04,S10j1002h06,S11k1103h06,S11k1103h21,S11l1130h20,S11l1130h24,S12n1223h20,S12o1225h20,S12p1228h22,S01aH08,S02aH08,S02e0215h20,S02f0216h22,S03aH06,S03aH07,S08h0819h02,S08i0820h21,S10aH02,S10aH06,S11aH06,S11k1103h20,S11l1130h02,S11l1130h04,S12n1223h06,S12n1223h23,S12o1225h21,S12o1225h22,S12p1228h06,S01b0107h22,S02e0215h19,S05g0526h04,S06aH07,S07aH07,S07aH08,S08aH08,S08h0819h05,S08h0819h24,S11l1130h01,S11l1130h19,S12m1222h24,S12o1225h02,S12p1228h03,S12p1228h05,S01aH07,S02aH07,S02d0204h03,S02d0204h05,S02d0204h21,S05aH01,S07aH02,S07aH06,S08h0819h22,S12n1223h03,S12n1223h19,S01b0107h19,S01c0130h01,S04aH08,S05g0526h03,S06aH01,S08h0819h03,S08i0820h19,S08i0820h22,S10j1002h02,S10j1002h05,S10j1002h24,S11k1103h04,S12aH08,S12m1222h22,S01b0107h02,S01b0107h03,S05aH08,S05g0526h06,S05g0526h23,S08aH02,S08h0819h21,S09aH06,S10aH08,S10j1002h04,S11k1103h24,S12m1222h02,S12m1222h20,S12m1222h21,S12n1223h22,S12n1223h24,S12o1225h24,S01aH06,S01b0107h24,S02d0204h01,S02d0204h23,S02e0215h03,S02e0215h21,S02e0215h22,S02f0216h05,S05aH07,S07aH01,S08aH06,S08h0819h06,S10aH07,S11k1103h22,S11l1130h23,S12m1222h06,S01aH01,S01b0107h01,S01b0107h23,S02d0204h02,S02d0204h06,S02e0215h01,S02e0215h06,S02f0216h03,S04aH01,S04aH06,S05g0526h19,S05g0526h21,S05g0526h22,S06aH02,S08i0820h01,S08i0820h23,S09aH08,S10j1002h22,S11aH01,S11l1130h06,S12aH06,S12p1228h24,S02aH06,S02d0204h24,S02f0216h04,S02f0216h19,S02f0216h21,S03aH08,S04aH07,S06aH08,S11aH02,S12aH01,S12o1225h06,S12p1228h21,S12p1228h23,S01b0107h06,S01c0130h03,S01c0130h04,S01c0130h06,S08h0819h23,S08i0820h20,S09aH01,S10j1002h03,S10j1002h19,S11aH07,S11k1103h05,S11l1130h05,S12aH02,S12n1223h04,S01b0107h21,S01c0130h21,S02d0204h19,S02f0216h23,S04aH02,S05g0526h01,S08aH07,S08h0819h01,S08h0819h19,S09aH02,S10j1002h21,S11k1103h01,S11k1103h03,S01b0107h04,S01b0107h20,S03aH02,S05g0526h05,S08i0820h06,S11k1103h02,S12m1222h23,S12n1223h05,S12p1228h01,S01c0130h19,S02e0215h05,S02f0216h06,S05g0526h02,S05g0526h24,S08aH01,S08h0819h04,S08i0820h02,S08i0820h03,S09aH07,S10aH01,S11k1103h19,S11l1130h21,S11l1130h22,S12n1223h21,S12o1225h23,S12p1228h04,S01c0130h05,S02d0204h04,S02e0215h23,S02e0215h24,S02f0216h02,S02f0216h24,S03aH01,S08i0820h05,S10j1002h01,S10j1002h23,S11l1130h03,S12aH07,S12m1222h01,S12o1225h01,S12o1225h05,S12p1228h19,S12p1228h20,S01aH02,S01b0107h05,S01c0130h02,S01c0130h20,S01c0130h24,S02f0216h20,S05g0526h20,S08h0819h20,S10j1002h20,S11k1103h23,S12m1222h03,S12m1222h19,S12n1223h01,S12n1223h02,S01c0130h23,S02aH02,S02d0204h20,S02d0204h22,S02e0215h02,S06aH06,S08i0820h24,S11aH08,S12m1222h04,S12m1222h05,S12o1225h03,S12o1225h04,S12o1225h19,S12p1228h02 | I12: N | J12: S06b0606h23,S06b0607h01,S06b0607h19,S06b0609h02,S06b0610h23,S08aH01,S08c0820h21,S08c0820h24,S08c0822h19,S08c0822h24,S08c0824h21,S08c0824h22,S08c0824h24,S08c0825h03,S08c0825h22,S08c0825h23,S08c0826h01,S09aH07,S10aH01,S04aH02,S06b0604h04,S06b0608h02,S06b0608h20,S06b0610h05,S06b0610h21,S08aH07,S08c0821h06,S08c0821h22,S08c0822h01,S08c0823h05,S08c0826h19,S08c0826h20,S09aH02,S04aH08,S06aH01,S06b0604h21,S06b0606h22,S06b0609h04,S06b0610h02,S08c0821h19,S08c0824h01,S12aH08,S12e1225h21,S02aH01,S05aH02,S05aH06,S06b0604h05,S06b0608h21,S06b0609h03,S06b0609h20,S06b0609h23,S08c0823h03,S08c0823h22,S08c0823h24,S08c0824h20,S08c0825h01,S08c0825h05,S08c0826h05,S12e1225h01,S12e1225h05,S12e1225h19,S01aH02,S06b0604h20,S06b0604h23,S06b0606h02,S06b0606h03,S06b0607h05,S06b0607h21,S06b0609h21,S06b0610h06,S08c0820h03,S08c0823h04,S08c0824h23,S08c0826h03,S02aH02,S06aH06,S06b0604h02,S06b0608h03,S08c0820h02,S08c0821h02,S08c0821h21,S08c0823h02,S08c0825h21,S11aH08,S12d1223h06,S12d1223h20,S12d1223h23,S12e1225h20,S05aH08,S06b0607h20,S06b0610h24,S08aH02,S08c0822h23,S08c0823h21,S08c0824h06,S08c0824h19,S09aH06,S10aH08,S12d1223h02,S01aH01,S04aH01,S04aH06,S06aH02,S06b0605h22,S06b0608h01,S06b0608h05,S06b0608h06,S06b0608h22,S06b0609h05,S08c0821h20,S08c0823h01,S08c0823h20,S08c0824h05,S08c0826h02,S08c0826h04,S08c0826h21,S09aH08,S11aH01,S12aH06,S02aH06,S03aH08,S04aH07,S06aH08,S06b0604h01,S06b0604h19,S06b0605h01,S06b0605h02,S06b0605h03,S06b0605h21,S06b0606h04,S06b0606h05,S06b0606h19,S06b0607h02,S06b0608h04,S08c0820h04,S08c0820h20,S08c0821h05,S08c0821h23,S08c0822h04,S08c0822h20,S08c0822h21,S11aH02,S12aH01,S12d1223h03,S06b0607h04,S06b0607h23,S06b0608h23,S08c0824h02,S08c0824h03,S08c0824h04,S08c0825h06,S09aH01,S11aH07,S12aH02,S12d1223h19,S12e1225h23,S12e1225h24,S01aH08,S02aH08,S03aH06,S03aH07,S06b0606h01,S06b0610h01,S06b0610h03,S08c0820h23,S08c0821h03,S08c0822h05,S08c0822h22,S08c0823h23,S08c0825h20,S08c0826h06,S08c0826h23,S10aH02,S10aH06,S11aH06,S12d1223h21,S12d1223h24,S12e1225h02,S12e1225h04,S03aH02,S06b0604h22,S06b0604h24,S06b0606h06,S06b0606h20,S06b0607h22,S06b0609h19,S06b0610h19,S06b0610h20,S08c0820h06,S08c0821h01,S08c0822h06,S08c0825h24,S08c0826h22,S12d1223h04,S12e1225h06,S01aH07,S02aH07,S05aH01,S06b0605h20,S06b0606h24,S06b0609h06,S06b0610h04,S07aH02,S07aH06,S08c0820h01,S08c0820h19,S08c0821h04,S08c0821h24,S08c0822h03,S08c0823h19,S08c0825h19,S12e1225h03,S01aH06,S05aH07,S06b0605h24,S06b0607h06,S06b0607h24,S06b0610h22,S07aH01,S08aH06,S08c0820h05,S08c0822h02,S08c0823h06,S08c0825h04,S10aH07,S12d1223h01,S12d1223h05,S03aH01,S06b0604h03,S06b0604h06,S06b0605h04,S06b0605h05,S06b0605h06,S06b0607h03,S06b0608h19,S06b0608h24,S06b0609h01,S08c0820h22,S08c0825h02,S08c0826h24,S12aH07,S12e1225h22,S06aH07,S06b0605h19,S06b0605h23,S06b0606h21,S06b0609h22,S06b0609h24,S07aH07,S07aH08,S08aH08,S12d1223h22 | L12: N | M12: S03aH02,S01aH02,S03aH03,S02aH03,S02aH02,S01aH03 | O12: N | P12: S03aH01,S02aH06,S03aH05,S05aH05,S04aH05,S06aH01,S02aH05,S03aH02,S07aH05,S01aH05,S03aH06,S06aH05,S02aH01,S05aH02,S05aH06,S04aH02,S02aH02,S06aH06,S05aH01,S07aH02,S07aH06,S01aH06,S07aH01,S01aH01,S04aH01,S04aH06,S06aH02,S01aH02 | R12: N | S12: S08aH01,S09aH07,S10aH01,S03aH02,S06aH07,S07aH07,S07aH08,S08aH08,S01aH01,S04aH01,S04aH06,S06aH02,S09aH08,S11aH01,S12aH06,S02aH02,S06aH06,S11aH08,S01aH07,S02aH07,S05aH01,S07aH02,S07aH06,S01aH06,S05aH07,S07aH01,S08aH06,S10aH07,S09aH01,S11aH07,S12aH02,S01aH02,S05aH08,S08aH02,S09aH06,S10aH08,S02aH06,S03aH08,S04aH07,S06aH08,S11aH02,S12aH01,S04aH02,S08aH07,S09aH02,S03aH01,S12aH07,S04aH08,S06aH01,S12aH08,S02aH01,S05aH02,S05aH06,S01aH08,S02aH08,S03aH06,S03aH07,S10aH02,S10aH06,S11aH06 | U12: N | V12: S02aH01,S05aH02,S05aH06,S02aH06,S03aH08,S04aH07,S06aH08,S11aH02,S12aH01,S05aH08,S08aH02,S09aH06,S10aH08,S04aH02,S08aH07,S09aH02,S03aH02,S03aH01,S12aH07,S01aH08,S02aH08,S03aH06,S03aH07,S10aH02,S10aH06,S11aH06,S09aH01,S11aH07,S12aH02,S01aH01,S04aH01,S04aH06,S06aH02,S09aH08,S11aH01,S12aH06,S01aH06,S05aH07,S07aH01,S08aH06,S10aH07,S02aH02,S06aH06,S11aH08,S04aH08,S06aH01,S12aH08,S08aH01,S09aH07,S10aH01,S06aH07,S07aH07,S07aH08,S08aH08,S01aH07,S02aH07,S05aH01,S07aH02,S07aH06,S01aH02 | X12: N | Y12: S02aH06,S03aH08,S04aH07,S06aH08,S11aH02,S12aH01,S01aH01,S04aH01,S04aH06,S06aH02,S09aH08,S11aH01,S12aH06,S02aH01,S05aH02,S05aH06,S03aH01,S12aH07,S01aH08,S02aH08,S03aH06,S03aH07,S10aH02,S10aH06,S11aH06,S06aH07,S07aH07,S07aH08,S08aH08,S03aH02,S01aH02,S02aH02,S06aH06,S11aH08,S01aH07,S02aH07,S05aH01,S07aH02,S07aH06,S04aH02,S08aH07,S09aH02,S04aH08,S06aH01,S12aH08,S08aH01,S09aH07,S10aH01,S01aH06,S05aH07,S07aH01,S08aH06,S10aH07,S09aH01,S11aH07,S12aH02,S05aH08,S08aH02,S09aH06,S10aH08 | AA12: N | AB12: AllSaAllH | AD12: N | AE12: FaP,SaP,SaN,WaN,RaP,WaP,FaN,RaN
I17: 0.75 | K17: share of charging at night
C18: ~UC_Sets: R_E: AllRegions
H21: =IF(H23=H24,"Not Required!","~UC_T: LO") -> Not Required!
C22: UC_N | D22: Pset_CI | E22: Pset_CO | F22: pset_pn | G22: Cset_CN | H22: TimeSlice | I22: UC_FLO | J22: UC_RHSRT | K22: UC_RHSRT~0
C23: UC_bev night chg limit | D23: ELC | E23: =G23 -> AuxStoIN | F23: *EV* | G23: AuxStoIN | H23: =HLOOKUP($A$10,$D$10:$CU$12,3,FALSE) -> AllSaAllH | I23: =1+I24 -> 0.25 | J23: 0 | K23: 3 | M23: night
D24: ELC | E24: =G24 -> AuxStoIN | F24: *EV* | G24: AuxStoIN | H24: =HLOOKUP($A$10,$D$10:$CU$12,2,FALSE) -> AllSaAllH | I24: =-$I$17 -> -0.75 | M24: day

Sheet s1p1v1_d
C9: =IF(A11="x","DeActivated","~TimeSlices") -> DeActivated | I9: =IF(A11="x","DeActivated","~TFM_DINS-AT") -> DeActivated | N9: =IF(A11="x","DeActivated","~TFM_DINS-AT") -> DeActivated | S9: =IF(A11="x","DeActivated","~TFM_DINS-AT") -> DeActivated | X9: =IF(A11="x","DeActivated","~TFM_DINS-AT") -> DeActivated | AC9: =IF(A11="x","DeActivated","~TFM_DINS-AT") -> DeActivated | AG9: =IF(A11="x","DeActivated","~TFM_DINS-AT") -> DeActivated | AK9: =IF(A11="x","DeActivated","~TFM_INS-AT") -> DeActivated
A10: s1p1v1_d | C10: season | D10: weekly | E10: daynite | F10: wparent | G10: dparent | I10: commodity | J10: timeslice | K10: com_fr | L10: process | N10: commodity | O10: timeslice | P10: com_fr | Q10: process | S10: commodity | T10: timeslice | U10: com_fr | V10: process | X10: g_yrfr | Y10: com_fr | Z10: timeslice | AA10: commodity | AC10: commodity | AD10: timeslice | AE10: com_fr | AG10: commodity | AH10: timeslice | AI10: com_pkflx | AK10: Year | AL10: timeslice | AM10: ncap_afs | AN10: pset_ci
A11: =IFERROR(IF(Veda!D5=A10,"ok","x"),"") -> x | C11: S01 | D11: a | E11: 0216h01 | F11: S01,S02,S03,S04,S05,S06,S07,S08,S09,S10,S11,S12 | G11: b | I11: elc_spv_001 | J11: S01aH01 | K11: 0 | L11: IMPNRGZ | N11: elc_won_001 | O11: S01aH01 | P11: 0.019486302 | Q11: IMPNRGZ | S11: elc_wof_001 | T11: S01aH01 | U11: 0.021480466 | V11: IMPNRGZ | X11: 0.017694064 | Y11: 0.0027539799 | Z11: S01aH01 | AA11: elc_roadtransport | AC11: elc_buildings | AD11: S01aH01 | AE11: 0.018478957 | AG11: ELC | AH11: S01aH01 | AI11: 0.146639 | AK11: 2020 | AL11: S01 | AM11: 0 | AN11: hydro
C12: S02 | D12: b | E12: 0216h02 | F12: S02 | G12: b | I12: elc_spv_001 | J12: S01aH02 | K12: 0 | L12: IMPNRGZ | N12: elc_won_001 | O12: S01aH02 | P12: 0.0039381276 | Q12: IMPNRGZ | S12: elc_wof_001 | T12: S01aH02 | U12: 0.0042989738 | V12: IMPNRGZ | X12: 0.0035388128 | Y12: 0.0017880317 | Z12: S01aH02 | AA12: elc_roadtransport | AC12: elc_buildings | AD12: S01aH02 | AE12: 0.0041712446 | AG12: ELC | AH12: S01aH02 | AI12: 0.075518054 | AK12: 2020 | AL12: S02 | AM12: 0 | AN12: hydro
C13: S03 | D13: c | E13: 0216h03 | F13: S11 | G13: b | I13: elc_spv_001 | J13: S01aH03 | K13: 0.0082448109 | L13: IMPNRGZ | N13: elc_won_001 | O13: S01aH03 | P13: 0.038022679 | Q13: IMPNRGZ | S13: elc_wof_001 | T13: S01aH03 | U13: 0.03649151 | V13: IMPNRGZ | X13: 0.031849315 | Y13: 0.042573652 | Z13: S01aH03 | AA13: elc_roadtransport | AC13: elc_buildings | AD13: S01aH03 | AE13: 0.038466888 | AG13: ELC | AH13: S01aH03 | AI13: 0.06036555 | AK13: 2020 | AL13: S03 | AM13: 0 | AN13: hydro
C14: S04 | D14: d | E14: 0216h04 | F14: S12 | G14: b | I14: elc_spv_001 | J14: S01aH04 | K14: 0.0014127397 | L14: IMPNRGZ | N14: elc_won_001 | O14: S01aH04 | P14: 0.0043550583 | Q14: IMPNRGZ | S14: elc_wof_001 | T14: S01aH04 | U14: 0.0041733096 | V14: IMPNRGZ | X14: 0.0035388128 | Y14: 0.0053435431 | Z14: S01aH04 | AA14: elc_roadtransport | AC14: elc_buildings | AD14: S01aH04 | AE14: 0.0043174705 | AG14: ELC | AH14: S01aH04 | AI14: 0.035756594 | AK14: 2020 | AL14: S04 | AM14: 0 | AN14: hydro
C15: S05 | E15: 0216h05 | G15: b | I15: elc_spv_001 | J15: S01aH05 | K15: 0.00061816345 | L15: IMPNRGZ | N15: elc_won_001 | O15: S01aH05 | P15: 0.012544254 | Q15: IMPNRGZ | S15: elc_wof_001 | T15: S01aH05 | U15: 0.012528104 | V15: IMPNRGZ | X15: 0.010616438 | Y15: 0.019113443 | Z15: S01aH05 | AA15: elc_roadtransport | AC15: elc_buildings | AD15: S01aH05 | AE15: 0.012948167 | AG15: ELC | AH15: S01aH05 | AI15: 0.037514711 | AK15: 2020 | AL15: S05 | AM15: 0 | AN15: hydro
C16: S06 | E16: 0216h06 | G16: b | I16: elc_spv_001 | J16: S01aH06 | K16: 0 | L16: IMPNRGZ | N16: elc_won_001 | O16: S01aH06 | P16: 0.0040373608 | Q16: IMPNRGZ | S16: elc_wof_001 | T16: S01aH06 | U16: 0.0040092314 | V16: IMPNRGZ | X16: 0.0035388128 | Y16: 0.0048297409 | Z16: S01aH06 | AA16: elc_roadtransport | AC16: elc_buildings | AD16: S01aH06 | AE16: 0.0042717407 | AG16: ELC | AH16: S01aH06 | AI16: 0.034365936 | AK16: 2020 | AL16: S06 | AM16: 0 | AN16: hydro
C17: S07 | E17: 0216h07 | G17: b | I17: elc_spv_001 | J17: S01aH07 | K17: 0 | L17: IMPNRGZ | N17: elc_won_001 | O17: S01aH07 | P17: 0.0039897057 | Q17: IMPNRGZ | S17: elc_wof_001 | T17: S01aH07 | U17: 0.0038701318 | V17: IMPNRGZ | X17: 0.0035388128 | Y17: 0.0033910946 | Z17: S01aH07 | AA17: elc_roadtransport | AC17: elc_buildings | AD17: S01aH07 | AE17: 0.0041027868 | AG17: ELC | AH17: S01aH07 | AI17: 0.035280814 | AK17: 2020 | AL17: S07 | AM17: 0 | AN17: hydro
C18: S08 | E18: 0216h08 | G18: b | I18: elc_spv_001 | J18: S01aH08 | K18: 0 | L18: IMPNRGZ | N18: elc_won_001 | O18: S01aH08 | P18: 0.011854357 | Q18: IMPNRGZ | S18: elc_wof_001 | T18: S01aH08 | U18: 0.01118305 | V18: IMPNRGZ | X18: 0.010616438 | Y18: 0.0051380222 | Z18: S01aH08 | AA18: elc_roadtransport | AC18: elc_buildings | AD18: S01aH08 | AE18: 0.011227685 | AG18: ELC | AH18: S01aH08 | AI18: 0.066865784 | AK18: 2020 | AL18: S08 | AM18: 0 | AN18: hydro
C19: S09 | E19: 0216h09 | G19: b | I19: elc_spv_001 | J19: S02aH01 | K19: 0 | L19: IMPNRGZ | N19: elc_won_001 | O19: S02aH01 | P19: 0.011726244 | Q19: IMPNRGZ | S19: elc_wof_001 | T19: S02aH01 | U19: 0.0084913135 | V19: IMPNRGZ | X19: 0.015410959 | Y19: 0.0023986277 | Z19: S02aH01 | AA19: elc_roadtransport | AC19: elc_buildings | AD19: S02aH01 | AE19: 0.015997743 | AG19: ELC | AH19: S02aH01 | AI19: 0.14892898 | AK19: 2020 | AL19: S09 | AM19: 0 | AN19: hydro
C20: S10 | E20: 0216h10 | G20: b | I20: elc_spv_001 | J20: S02aH02 | K20: 0 | L20: IMPNRGZ | N20: elc_won_001 | O20: S02aH02 | P20: 0.0025260938 | Q20: IMPNRGZ | S20: elc_wof_001 | T20: S02aH02 | U20: 0.0018076768 | V20: IMPNRGZ | X20: 0.0030821918 | Y20: 0.001557318 | Z20: S02aH02 | AA20: elc_roadtransport | AC20: elc_buildings | AD20: S02aH02 | AE20: 0.0035498882 | AG20: ELC | AH20: S02aH02 | AI20: 0.085662968 | AK20: 2020 | AL20: S10 | AM20: 0 | AN20: hydro
C21: S11 | E21: 0216h11 | G21: b | I21: elc_spv_001 | J21: S02aH03 | K21: 0.019846471 | L21: IMPNRGZ | N21: elc_won_001 | O21: S02aH03 | P21: 0.023514867 | Q21: IMPNRGZ | S21: elc_wof_001 | T21: S02aH03 | U21: 0.017918971 | V21: IMPNRGZ | X21: 0.027739726 | Y21: 0.037080277 | Z21: S02aH03 | AA21: elc_roadtransport | AC21: elc_buildings | AD21: S02aH03 | AE21: 0.031560017 | AG21: ELC | AH21: S02aH03 | AI21: 0.063317415 | AK21: 2020 | AL21: S11 | AM21: 0 | AN21: hydro
C22: S12 | E22: 0216h12 | G22: b | I22: elc_spv_001 | J22: S02aH04 | K22: 0.0033820799 | L22: IMPNRGZ | N22: elc_won_001 | O22: S02aH04 | P22: 0.0025886779 | Q22: IMPNRGZ | S22: elc_wof_001 | T22: S02aH04 | U22: 0.0021792842 | V22: IMPNRGZ | X22: 0.0030821918 | Y22: 0.0046540537 | Z22: S02aH04 | AA22: elc_roadtransport | AC22: elc_buildings | AD22: S02aH04 | AE22: 0.0035450962 | AG22: ELC | AH22: S02aH04 | AI22: 0.01473147 | AK22: 2020 | AL22: S12 | AM22: 0 | AN22: hydro
E23: 0216h13 | G23: b | I23: elc_spv_001 | J23: S02aH05 | K23: 0.0035497246 | L23: IMPNRGZ | N23: elc_won_001 | O23: S02aH05 | P23: 0.0077531587 | Q23: IMPNRGZ | S23: elc_wof_001 | T23: S02aH05 | U23: 0.006988494 | V23: IMPNRGZ | X23: 0.0092465753 | Y23: 0.016647192 | Z23: S02aH05 | AA23: elc_roadtransport | AC23: elc_buildings | AD23: S02aH05 | AE23: 0.010635289 | AG23: ELC | AH23: S02aH05 | AI23: 0.033522793 | AK23: 2021 | AL23: S01 | AM23: 0 | AN23: hydro
E24: 0216h14 | G24: b | I24: elc_spv_001 | J24: S02aH06 | K24: 0 | L24: IMPNRGZ | N24: elc_won_001 | O24: S02aH06 | P24: 0.002586946 | Q24: IMPNRGZ | S24: elc_wof_001 | T24: S02aH06 | U24: 0.0023352065 | V24: IMPNRGZ | X24: 0.0030821918 | Y24: 0.0042065485 | Z24: S02aH06 | AA24: elc_roadtransport | AC24: elc_buildings | AD24: S02aH06 | AE24: 0.0035434532 | AG24: ELC | AH24: S02aH06 | AI24: 0.030749594 | AK24: 2021 | AL24: S02 | AM24: 0 | AN24: hydro
E25: 0216h15 | G25: b | I25: elc_spv_001 | J25: S02aH07 | K25: 0 | L25: IMPNRGZ | N25: elc_won_001 | O25: S02aH07 | P25: 0.0025187123 | Q25: IMPNRGZ | S25: elc_wof_001 | T25: S02aH07 | U25: 0.0021584117 | V25: IMPNRGZ | X25: 0.0030821918 | Y25: 0.002953534 | Z25: S02aH07 | AA25: elc_roadtransport | AC25: elc_buildings | AD25: S02aH07 | AE25: 0.0033582064 | AG25: ELC | AH25: S02aH07 | AI25: 0.03209638 | AK25: 2021 | AL25: S03 | AM25: 0 | AN25: hydro
E26: 0216h16 | G26: b | I26: elc_spv_001 | J26: S02aH08 | K26: 0 | L26: IMPNRGZ | N26: elc_won_001 | O26: S02aH08 | P26: 0.0067928268 | Q26: IMPNRGZ | S26: elc_wof_001 | T26: S02aH08 | U26: 0.0061625217 | V26: IMPNRGZ | X26: 0.0092465753 | Y26: 0.0044750516 | Z26: S02aH08 | AA26: elc_roadtransport | AC26: elc_buildings | AD26: S02aH08 | AE26: 0.0095450296 | AG26: ELC | AH26: S02aH08 | AI26: 0.037428395 | AK26: 2021 | AL26: S04 | AM26: 0 | AN26: hydro
E27: 0216h17 | G27: b | I27: elc_spv_001 | J27: S02b0216h01 | K27: 0 | L27: IMPNRGZ | N27: elc_won_001 | O27: S02b0216h01 | P27: 3.3850851e-06 | Q27: IMPNRGZ | S27: elc_wof_001 | T27: S02b0216h01 | U27: 0 | V27: IMPNRGZ | X27: 0.00011415525 | Y27: 2.1546545e-05 | Z27: S02b0216h01 | AA27: elc_roadtransport | AC27: elc_buildings | AD27: S02b0216h01 | AE27: 0.00011539229 | AG27: ELC | AH27: S02b0216h01 | AI27: 0 | AK27: 2021 | AL27: S05 | AM27: 0 | AN27: hydro
E28: 0216h18 | G28: b | I28: elc_spv_001 | J28: S02b0216h02 | K28: 0 | L28: IMPNRGZ | N28: elc_won_001 | O28: S02b0216h02 | P28: 2.2013003e-06 | Q28: IMPNRGZ | S28: elc_wof_001 | T28: S02b0216h02 | U28: 0 | V28: IMPNRGZ | X28: 0.00011415525 | Y28: 1.4916839e-05 | Z28: S02b0216h02 | AA28: elc_roadtransport | AC28: elc_buildings | AD28: S02b0216h02 | AE28: 0.0001145708 | AG28: ELC | AH28: S02b0216h02 | AI28: 0 | AK28: 2021 | AL28: S06 | AM28: 0 | AN28: hydro
E29: 0216h19 | G29: b | I29: elc_spv_001 | J29: S02b0216h03 | K29: 0 | L29: IMPNRGZ | N29: elc_won_001 | O29: S02b0216h03 | P29: 1.3836702e-06 | Q29: IMPNRGZ | S29: elc_wof_001 | T29: S02b0216h03 | U29: 0 | V29: IMPNRGZ | X29: 0.00011415525 | Y29: 1.6574265e-05 | Z29: S02b0216h03 | AA29: elc_roadtransport | AC29: elc_buildings | AD29: S02b0216h03 | AE29: 0.00011539229 | AG29: ELC | AH29: S02b0216h03 | AI29: 0 | AK29: 2021 | AL29: S07 | AM29: 0 | AN29: hydro
E30: 0216h20 | G30: b | I30: elc_spv_001 | J30: S02b0216h04 | K30: 0 | L30: IMPNRGZ | N30: elc_won_001 | O30: S02b0216h04 | P30: 9.1660054e-07 | Q30: IMPNRGZ | S30: elc_wof_001 | T30: S02b0216h04 | U30: 0 | V30: IMPNRGZ | X30: 0.00011415525 | Y30: 1.4585353e-05 | Z30: S02b0216h04 | AA30: elc_roadtransport | AC30: elc_buildings | AD30: S02b0216h04 | AE30: 0.00011484463 | AG30: ELC | AH30: S02b0216h04 | AI30: 0 | AK30: 2021 | AL30: S08 | AM30: 0 | AN30: hydro
E31: 0216h21 | G31: b | I31: elc_spv_001 | J31: S02b0216h05 | K31: 0 | L31: IMPNRGZ | N31: elc_won_001 | O31: S02b0216h05 | P31: 8.5088526e-07 | Q31: IMPNRGZ | S31: elc_wof_001 | T31: S02b0216h05 | U31: 0 | V31: IMPNRGZ | X31: 0.00011415525 | Y31: 2.1215059e-05 | Z31: S02b0216h05 | AA31: elc_roadtransport | AC31: elc_buildings | AD31: S02b0216h05 | AE31: 0.00011155866 | AG31: ELC | AH31: S02b0216h05 | AI31: 0 | AK31: 2021 | AL31: S09 | AM31: 0 | AN31: hydro
E32: 0216h22 | G32: b | I32: elc_spv_001 | J32: S02b0216h06 | K32: 0 | L32: IMPNRGZ | N32: elc_won_001 | O32: S02b0216h06 | P32: 1.4902388e-06 | Q32: IMPNRGZ | S32: elc_wof_001 | T32: S02b0216h06 | U32: 1.027515e-06 | V32: IMPNRGZ | X32: 0.00011415525 | Y32: 5.7678443e-05 | Z32: S02b0216h06 | AA32: elc_roadtransport | AC32: elc_buildings | AD32: S02b0216h06 | AE32: 0.00011361239 | AG32: ELC | AH32: S02b0216h06 | AI32: 0 | AK32: 2021 | AL32: S10 | AM32: 0 | AN32: hydro
E33: 0216h23 | G33: b | I33: elc_spv_001 | J33: S02b0216h07 | K33: 0 | L33: IMPNRGZ | N33: elc_won_001 | O33: S02b0216h07 | P33: 3.2810061e-06 | Q33: IMPNRGZ | S33: elc_wof_001 | T33: S02b0216h07 | U33: 9.8119097e-07 | V33: IMPNRGZ | X33: 0.00011415525 | Y33: 0.0001690575 | Z33: S02b0216h07 | AA33: elc_roadtransport | AC33: elc_buildings | AD33: S02b0216h07 | AE33: 0.00011936285 | AG33: ELC | AH33: S02b0216h07 | AI33: 0 | AK33: 2021 | AL33: S11 | AM33: 0 | AN33: hydro
